{
 "cells": [
  {
   "cell_type": "code",
   "execution_count": null,
   "id": "c0a5e8e0",
   "metadata": {},
   "outputs": [
    {
     "name": "stderr",
     "output_type": "stream",
     "text": [
      "ERROR:root:Internal Python error in the inspect module.\n",
      "Below is the traceback from this internal error.\n",
      "\n",
      "ERROR:root:Internal Python error in the inspect module.\n",
      "Below is the traceback from this internal error.\n",
      "\n",
      "ERROR:root:Internal Python error in the inspect module.\n",
      "Below is the traceback from this internal error.\n",
      "\n"
     ]
    },
    {
     "name": "stdout",
     "output_type": "stream",
     "text": [
      "Traceback (most recent call last):\n",
      "  File \"C:\\Users\\14435\\anaconda3\\envs\\tensorflow\\lib\\site-packages\\IPython\\core\\interactiveshell.py\", line 3457, in run_code\n",
      "    exec(code_obj, self.user_global_ns, self.user_ns)\n",
      "  File \"C:\\Users\\14435\\AppData\\Local\\Temp\\ipykernel_194552\\2246566909.py\", line 3, in <module>\n",
      "    from tensorflow.keras import layers, models, utils\n",
      "  File \"C:\\Users\\14435\\anaconda3\\envs\\tensorflow\\lib\\site-packages\\tensorflow\\__init__.py\", line 101, in <module>\n",
      "    from tensorflow_core import *\n",
      "  File \"C:\\Users\\14435\\anaconda3\\envs\\tensorflow\\lib\\site-packages\\tensorflow_core\\__init__.py\", line 40, in <module>\n",
      "    from tensorflow.python.tools import module_util as _module_util\n",
      "  File \"<frozen importlib._bootstrap>\", line 983, in _find_and_load\n",
      "  File \"<frozen importlib._bootstrap>\", line 959, in _find_and_load_unlocked\n",
      "  File \"C:\\Users\\14435\\anaconda3\\envs\\tensorflow\\lib\\site-packages\\tensorflow\\__init__.py\", line 50, in __getattr__\n",
      "    module = self._load()\n",
      "  File \"C:\\Users\\14435\\anaconda3\\envs\\tensorflow\\lib\\site-packages\\tensorflow\\__init__.py\", line 44, in _load\n",
      "    module = _importlib.import_module(self.__name__)\n",
      "  File \"C:\\Users\\14435\\anaconda3\\envs\\tensorflow\\lib\\importlib\\__init__.py\", line 127, in import_module\n",
      "    return _bootstrap._gcd_import(name[level:], package, level)\n",
      "  File \"C:\\Users\\14435\\anaconda3\\envs\\tensorflow\\lib\\site-packages\\tensorflow_core\\python\\__init__.py\", line 64, in <module>\n",
      "    from tensorflow.core.framework.graph_pb2 import *\n",
      "  File \"C:\\Users\\14435\\anaconda3\\envs\\tensorflow\\lib\\site-packages\\tensorflow_core\\core\\framework\\graph_pb2.py\", line 16, in <module>\n",
      "    from tensorflow.core.framework import node_def_pb2 as tensorflow_dot_core_dot_framework_dot_node__def__pb2\n",
      "  File \"C:\\Users\\14435\\anaconda3\\envs\\tensorflow\\lib\\site-packages\\tensorflow_core\\core\\framework\\node_def_pb2.py\", line 16, in <module>\n",
      "    from tensorflow.core.framework import attr_value_pb2 as tensorflow_dot_core_dot_framework_dot_attr__value__pb2\n",
      "  File \"C:\\Users\\14435\\anaconda3\\envs\\tensorflow\\lib\\site-packages\\tensorflow_core\\core\\framework\\attr_value_pb2.py\", line 16, in <module>\n",
      "    from tensorflow.core.framework import tensor_pb2 as tensorflow_dot_core_dot_framework_dot_tensor__pb2\n",
      "  File \"C:\\Users\\14435\\anaconda3\\envs\\tensorflow\\lib\\site-packages\\tensorflow_core\\core\\framework\\tensor_pb2.py\", line 16, in <module>\n",
      "    from tensorflow.core.framework import resource_handle_pb2 as tensorflow_dot_core_dot_framework_dot_resource__handle__pb2\n",
      "  File \"C:\\Users\\14435\\anaconda3\\envs\\tensorflow\\lib\\site-packages\\tensorflow_core\\core\\framework\\resource_handle_pb2.py\", line 16, in <module>\n",
      "    from tensorflow.core.framework import tensor_shape_pb2 as tensorflow_dot_core_dot_framework_dot_tensor__shape__pb2\n",
      "  File \"C:\\Users\\14435\\anaconda3\\envs\\tensorflow\\lib\\site-packages\\tensorflow_core\\core\\framework\\tensor_shape_pb2.py\", line 42, in <module>\n",
      "    serialized_options=None, file=DESCRIPTOR),\n",
      "  File \"C:\\Users\\14435\\anaconda3\\envs\\tensorflow\\lib\\site-packages\\google\\protobuf\\descriptor.py\", line 561, in __new__\n",
      "    _message.Message._CheckCalledFromGeneratedFile()\n",
      "TypeError: Descriptors cannot not be created directly.\n",
      "If this call came from a _pb2.py file, your generated code is out of date and must be regenerated with protoc >= 3.19.0.\n",
      "If you cannot immediately regenerate your protos, some other possible workarounds are:\n",
      " 1. Downgrade the protobuf package to 3.20.x or lower.\n",
      " 2. Set PROTOCOL_BUFFERS_PYTHON_IMPLEMENTATION=python (but this will use pure-Python parsing and will be much slower).\n",
      "\n",
      "More information: https://developers.google.com/protocol-buffers/docs/news/2022-05-06#python-updates\n",
      "\n",
      "During handling of the above exception, another exception occurred:\n",
      "\n",
      "Traceback (most recent call last):\n",
      "  File \"C:\\Users\\14435\\anaconda3\\envs\\tensorflow\\lib\\site-packages\\IPython\\core\\interactiveshell.py\", line 2077, in showtraceback\n",
      "    stb = value._render_traceback_()\n",
      "AttributeError: 'TypeError' object has no attribute '_render_traceback_'\n",
      "\n",
      "During handling of the above exception, another exception occurred:\n",
      "\n",
      "Traceback (most recent call last):\n",
      "  File \"C:\\Users\\14435\\anaconda3\\envs\\tensorflow\\lib\\site-packages\\IPython\\core\\ultratb.py\", line 1101, in get_records\n",
      "    return _fixed_getinnerframes(etb, number_of_lines_of_context, tb_offset)\n",
      "  File \"C:\\Users\\14435\\anaconda3\\envs\\tensorflow\\lib\\site-packages\\IPython\\core\\ultratb.py\", line 248, in wrapped\n",
      "    return f(*args, **kwargs)\n",
      "  File \"C:\\Users\\14435\\anaconda3\\envs\\tensorflow\\lib\\site-packages\\IPython\\core\\ultratb.py\", line 281, in _fixed_getinnerframes\n",
      "    records = fix_frame_records_filenames(inspect.getinnerframes(etb, context))\n",
      "  File \"C:\\Users\\14435\\anaconda3\\envs\\tensorflow\\lib\\inspect.py\", line 1502, in getinnerframes\n",
      "    frameinfo = (tb.tb_frame,) + getframeinfo(tb, context)\n",
      "  File \"C:\\Users\\14435\\anaconda3\\envs\\tensorflow\\lib\\inspect.py\", line 1460, in getframeinfo\n",
      "    filename = getsourcefile(frame) or getfile(frame)\n",
      "  File \"C:\\Users\\14435\\anaconda3\\envs\\tensorflow\\lib\\inspect.py\", line 696, in getsourcefile\n",
      "    if getattr(getmodule(object, filename), '__loader__', None) is not None:\n",
      "  File \"C:\\Users\\14435\\anaconda3\\envs\\tensorflow\\lib\\inspect.py\", line 733, in getmodule\n",
      "    if ismodule(module) and hasattr(module, '__file__'):\n",
      "  File \"C:\\Users\\14435\\anaconda3\\envs\\tensorflow\\lib\\site-packages\\tensorflow\\__init__.py\", line 50, in __getattr__\n",
      "    module = self._load()\n",
      "  File \"C:\\Users\\14435\\anaconda3\\envs\\tensorflow\\lib\\site-packages\\tensorflow\\__init__.py\", line 44, in _load\n",
      "    module = _importlib.import_module(self.__name__)\n",
      "  File \"C:\\Users\\14435\\anaconda3\\envs\\tensorflow\\lib\\importlib\\__init__.py\", line 127, in import_module\n",
      "    return _bootstrap._gcd_import(name[level:], package, level)\n",
      "  File \"<frozen importlib._bootstrap>\", line 1006, in _gcd_import\n",
      "  File \"<frozen importlib._bootstrap>\", line 983, in _find_and_load\n",
      "  File \"<frozen importlib._bootstrap>\", line 953, in _find_and_load_unlocked\n",
      "  File \"<frozen importlib._bootstrap>\", line 219, in _call_with_frames_removed\n",
      "  File \"<frozen importlib._bootstrap>\", line 1006, in _gcd_import\n",
      "  File \"<frozen importlib._bootstrap>\", line 983, in _find_and_load\n",
      "  File \"<frozen importlib._bootstrap>\", line 967, in _find_and_load_unlocked\n",
      "  File \"<frozen importlib._bootstrap>\", line 677, in _load_unlocked\n",
      "  File \"<frozen importlib._bootstrap_external>\", line 728, in exec_module\n",
      "  File \"<frozen importlib._bootstrap>\", line 219, in _call_with_frames_removed\n",
      "  File \"C:\\Users\\14435\\anaconda3\\envs\\tensorflow\\lib\\site-packages\\tensorflow_core\\__init__.py\", line 42, in <module>\n",
      "    from . _api.v2 import audio\n",
      "  File \"C:\\Users\\14435\\anaconda3\\envs\\tensorflow\\lib\\site-packages\\tensorflow_core\\_api\\v2\\audio\\__init__.py\", line 10, in <module>\n",
      "    from tensorflow.python.ops.gen_audio_ops import decode_wav\n",
      "  File \"C:\\Users\\14435\\anaconda3\\envs\\tensorflow\\lib\\site-packages\\tensorflow_core\\python\\ops\\gen_audio_ops.py\", line 9, in <module>\n",
      "    from tensorflow.python.eager import context as _context\n",
      "  File \"C:\\Users\\14435\\anaconda3\\envs\\tensorflow\\lib\\site-packages\\tensorflow_core\\python\\eager\\context.py\", line 29, in <module>\n",
      "    from tensorflow.core.protobuf import config_pb2\n",
      "  File \"C:\\Users\\14435\\anaconda3\\envs\\tensorflow\\lib\\site-packages\\tensorflow_core\\core\\protobuf\\config_pb2.py\", line 16, in <module>\n",
      "    from tensorflow.core.framework import cost_graph_pb2 as tensorflow_dot_core_dot_framework_dot_cost__graph__pb2\n",
      "  File \"C:\\Users\\14435\\anaconda3\\envs\\tensorflow\\lib\\site-packages\\tensorflow_core\\core\\framework\\cost_graph_pb2.py\", line 16, in <module>\n",
      "    from tensorflow.core.framework import tensor_shape_pb2 as tensorflow_dot_core_dot_framework_dot_tensor__shape__pb2\n",
      "  File \"C:\\Users\\14435\\anaconda3\\envs\\tensorflow\\lib\\site-packages\\tensorflow_core\\core\\framework\\tensor_shape_pb2.py\", line 42, in <module>\n",
      "    serialized_options=None, file=DESCRIPTOR),\n",
      "  File \"C:\\Users\\14435\\anaconda3\\envs\\tensorflow\\lib\\site-packages\\google\\protobuf\\descriptor.py\", line 561, in __new__\n",
      "    _message.Message._CheckCalledFromGeneratedFile()\n",
      "TypeError: Descriptors cannot not be created directly.\n",
      "If this call came from a _pb2.py file, your generated code is out of date and must be regenerated with protoc >= 3.19.0.\n",
      "If you cannot immediately regenerate your protos, some other possible workarounds are:\n",
      " 1. Downgrade the protobuf package to 3.20.x or lower.\n",
      " 2. Set PROTOCOL_BUFFERS_PYTHON_IMPLEMENTATION=python (but this will use pure-Python parsing and will be much slower).\n",
      "\n",
      "More information: https://developers.google.com/protocol-buffers/docs/news/2022-05-06#python-updates\n",
      "Traceback (most recent call last):\n",
      "  File \"C:\\Users\\14435\\anaconda3\\envs\\tensorflow\\lib\\site-packages\\IPython\\core\\interactiveshell.py\", line 3457, in run_code\n",
      "    exec(code_obj, self.user_global_ns, self.user_ns)\n",
      "  File \"C:\\Users\\14435\\AppData\\Local\\Temp\\ipykernel_194552\\2246566909.py\", line 3, in <module>\n",
      "    from tensorflow.keras import layers, models, utils\n",
      "  File \"C:\\Users\\14435\\anaconda3\\envs\\tensorflow\\lib\\site-packages\\tensorflow\\__init__.py\", line 101, in <module>\n",
      "    from tensorflow_core import *\n",
      "  File \"C:\\Users\\14435\\anaconda3\\envs\\tensorflow\\lib\\site-packages\\tensorflow_core\\__init__.py\", line 40, in <module>\n",
      "    from tensorflow.python.tools import module_util as _module_util\n",
      "  File \"<frozen importlib._bootstrap>\", line 983, in _find_and_load\n",
      "  File \"<frozen importlib._bootstrap>\", line 959, in _find_and_load_unlocked\n",
      "  File \"C:\\Users\\14435\\anaconda3\\envs\\tensorflow\\lib\\site-packages\\tensorflow\\__init__.py\", line 50, in __getattr__\n",
      "    module = self._load()\n",
      "  File \"C:\\Users\\14435\\anaconda3\\envs\\tensorflow\\lib\\site-packages\\tensorflow\\__init__.py\", line 44, in _load\n",
      "    module = _importlib.import_module(self.__name__)\n",
      "  File \"C:\\Users\\14435\\anaconda3\\envs\\tensorflow\\lib\\importlib\\__init__.py\", line 127, in import_module\n",
      "    return _bootstrap._gcd_import(name[level:], package, level)\n",
      "  File \"C:\\Users\\14435\\anaconda3\\envs\\tensorflow\\lib\\site-packages\\tensorflow_core\\python\\__init__.py\", line 64, in <module>\n",
      "    from tensorflow.core.framework.graph_pb2 import *\n",
      "  File \"C:\\Users\\14435\\anaconda3\\envs\\tensorflow\\lib\\site-packages\\tensorflow_core\\core\\framework\\graph_pb2.py\", line 16, in <module>\n",
      "    from tensorflow.core.framework import node_def_pb2 as tensorflow_dot_core_dot_framework_dot_node__def__pb2\n",
      "  File \"C:\\Users\\14435\\anaconda3\\envs\\tensorflow\\lib\\site-packages\\tensorflow_core\\core\\framework\\node_def_pb2.py\", line 16, in <module>\n",
      "    from tensorflow.core.framework import attr_value_pb2 as tensorflow_dot_core_dot_framework_dot_attr__value__pb2\n",
      "  File \"C:\\Users\\14435\\anaconda3\\envs\\tensorflow\\lib\\site-packages\\tensorflow_core\\core\\framework\\attr_value_pb2.py\", line 16, in <module>\n",
      "    from tensorflow.core.framework import tensor_pb2 as tensorflow_dot_core_dot_framework_dot_tensor__pb2\n",
      "  File \"C:\\Users\\14435\\anaconda3\\envs\\tensorflow\\lib\\site-packages\\tensorflow_core\\core\\framework\\tensor_pb2.py\", line 16, in <module>\n",
      "    from tensorflow.core.framework import resource_handle_pb2 as tensorflow_dot_core_dot_framework_dot_resource__handle__pb2\n",
      "  File \"C:\\Users\\14435\\anaconda3\\envs\\tensorflow\\lib\\site-packages\\tensorflow_core\\core\\framework\\resource_handle_pb2.py\", line 16, in <module>\n",
      "    from tensorflow.core.framework import tensor_shape_pb2 as tensorflow_dot_core_dot_framework_dot_tensor__shape__pb2\n",
      "  File \"C:\\Users\\14435\\anaconda3\\envs\\tensorflow\\lib\\site-packages\\tensorflow_core\\core\\framework\\tensor_shape_pb2.py\", line 42, in <module>\n",
      "    serialized_options=None, file=DESCRIPTOR),\n",
      "  File \"C:\\Users\\14435\\anaconda3\\envs\\tensorflow\\lib\\site-packages\\google\\protobuf\\descriptor.py\", line 561, in __new__\n",
      "    _message.Message._CheckCalledFromGeneratedFile()\n",
      "TypeError: Descriptors cannot not be created directly.\n",
      "If this call came from a _pb2.py file, your generated code is out of date and must be regenerated with protoc >= 3.19.0.\n",
      "If you cannot immediately regenerate your protos, some other possible workarounds are:\n",
      " 1. Downgrade the protobuf package to 3.20.x or lower.\n",
      " 2. Set PROTOCOL_BUFFERS_PYTHON_IMPLEMENTATION=python (but this will use pure-Python parsing and will be much slower).\n",
      "\n",
      "More information: https://developers.google.com/protocol-buffers/docs/news/2022-05-06#python-updates\n",
      "\n",
      "During handling of the above exception, another exception occurred:\n",
      "\n",
      "Traceback (most recent call last):\n",
      "  File \"C:\\Users\\14435\\anaconda3\\envs\\tensorflow\\lib\\site-packages\\IPython\\core\\interactiveshell.py\", line 2077, in showtraceback\n",
      "    stb = value._render_traceback_()\n",
      "AttributeError: 'TypeError' object has no attribute '_render_traceback_'\n",
      "\n",
      "During handling of the above exception, another exception occurred:\n",
      "\n",
      "Traceback (most recent call last):\n",
      "  File \"C:\\Users\\14435\\anaconda3\\envs\\tensorflow\\lib\\site-packages\\IPython\\core\\interactiveshell.py\", line 3377, in run_ast_nodes\n",
      "    if (await self.run_code(code, result,  async_=asy)):\n",
      "  File \"C:\\Users\\14435\\anaconda3\\envs\\tensorflow\\lib\\site-packages\\IPython\\core\\interactiveshell.py\", line 3474, in run_code\n",
      "    self.showtraceback(running_compiled_code=True)\n",
      "  File \"C:\\Users\\14435\\anaconda3\\envs\\tensorflow\\lib\\site-packages\\IPython\\core\\interactiveshell.py\", line 2080, in showtraceback\n",
      "    value, tb, tb_offset=tb_offset)\n",
      "  File \"C:\\Users\\14435\\anaconda3\\envs\\tensorflow\\lib\\site-packages\\IPython\\core\\ultratb.py\", line 1368, in structured_traceback\n",
      "    self, etype, value, tb, tb_offset, number_of_lines_of_context)\n",
      "  File \"C:\\Users\\14435\\anaconda3\\envs\\tensorflow\\lib\\site-packages\\IPython\\core\\ultratb.py\", line 1268, in structured_traceback\n",
      "    self, etype, value, tb, tb_offset, number_of_lines_of_context\n",
      "  File \"C:\\Users\\14435\\anaconda3\\envs\\tensorflow\\lib\\site-packages\\IPython\\core\\ultratb.py\", line 1125, in structured_traceback\n",
      "    tb_offset)\n",
      "  File \"C:\\Users\\14435\\anaconda3\\envs\\tensorflow\\lib\\site-packages\\IPython\\core\\ultratb.py\", line 1082, in format_exception_as_a_whole\n",
      "    last_unique, recursion_repeat = find_recursion(orig_etype, evalue, records)\n",
      "  File \"C:\\Users\\14435\\anaconda3\\envs\\tensorflow\\lib\\site-packages\\IPython\\core\\ultratb.py\", line 382, in find_recursion\n",
      "    return len(records), 0\n",
      "TypeError: object of type 'NoneType' has no len()\n",
      "\n",
      "During handling of the above exception, another exception occurred:\n",
      "\n",
      "Traceback (most recent call last):\n",
      "  File \"C:\\Users\\14435\\anaconda3\\envs\\tensorflow\\lib\\site-packages\\IPython\\core\\interactiveshell.py\", line 2077, in showtraceback\n",
      "    stb = value._render_traceback_()\n",
      "AttributeError: 'TypeError' object has no attribute '_render_traceback_'\n",
      "\n",
      "During handling of the above exception, another exception occurred:\n",
      "\n",
      "Traceback (most recent call last):\n",
      "  File \"C:\\Users\\14435\\anaconda3\\envs\\tensorflow\\lib\\site-packages\\IPython\\core\\ultratb.py\", line 1101, in get_records\n",
      "    return _fixed_getinnerframes(etb, number_of_lines_of_context, tb_offset)\n",
      "  File \"C:\\Users\\14435\\anaconda3\\envs\\tensorflow\\lib\\site-packages\\IPython\\core\\ultratb.py\", line 248, in wrapped\n",
      "    return f(*args, **kwargs)\n",
      "  File \"C:\\Users\\14435\\anaconda3\\envs\\tensorflow\\lib\\site-packages\\IPython\\core\\ultratb.py\", line 281, in _fixed_getinnerframes\n",
      "    records = fix_frame_records_filenames(inspect.getinnerframes(etb, context))\n",
      "  File \"C:\\Users\\14435\\anaconda3\\envs\\tensorflow\\lib\\inspect.py\", line 1502, in getinnerframes\n",
      "    frameinfo = (tb.tb_frame,) + getframeinfo(tb, context)\n",
      "  File \"C:\\Users\\14435\\anaconda3\\envs\\tensorflow\\lib\\inspect.py\", line 1460, in getframeinfo\n",
      "    filename = getsourcefile(frame) or getfile(frame)\n",
      "  File \"C:\\Users\\14435\\anaconda3\\envs\\tensorflow\\lib\\inspect.py\", line 696, in getsourcefile\n",
      "    if getattr(getmodule(object, filename), '__loader__', None) is not None:\n",
      "  File \"C:\\Users\\14435\\anaconda3\\envs\\tensorflow\\lib\\inspect.py\", line 733, in getmodule\n",
      "    if ismodule(module) and hasattr(module, '__file__'):\n",
      "  File \"C:\\Users\\14435\\anaconda3\\envs\\tensorflow\\lib\\site-packages\\tensorflow\\__init__.py\", line 50, in __getattr__\n",
      "    module = self._load()\n",
      "  File \"C:\\Users\\14435\\anaconda3\\envs\\tensorflow\\lib\\site-packages\\tensorflow\\__init__.py\", line 44, in _load\n",
      "    module = _importlib.import_module(self.__name__)\n",
      "  File \"C:\\Users\\14435\\anaconda3\\envs\\tensorflow\\lib\\importlib\\__init__.py\", line 127, in import_module\n",
      "    return _bootstrap._gcd_import(name[level:], package, level)\n",
      "  File \"<frozen importlib._bootstrap>\", line 1006, in _gcd_import\n",
      "  File \"<frozen importlib._bootstrap>\", line 983, in _find_and_load\n",
      "  File \"<frozen importlib._bootstrap>\", line 953, in _find_and_load_unlocked\n",
      "  File \"<frozen importlib._bootstrap>\", line 219, in _call_with_frames_removed\n",
      "  File \"<frozen importlib._bootstrap>\", line 1006, in _gcd_import\n",
      "  File \"<frozen importlib._bootstrap>\", line 983, in _find_and_load\n",
      "  File \"<frozen importlib._bootstrap>\", line 967, in _find_and_load_unlocked\n",
      "  File \"<frozen importlib._bootstrap>\", line 677, in _load_unlocked\n",
      "  File \"<frozen importlib._bootstrap_external>\", line 728, in exec_module\n",
      "  File \"<frozen importlib._bootstrap>\", line 219, in _call_with_frames_removed\n",
      "  File \"C:\\Users\\14435\\anaconda3\\envs\\tensorflow\\lib\\site-packages\\tensorflow_core\\__init__.py\", line 42, in <module>\n",
      "    from . _api.v2 import audio\n",
      "  File \"C:\\Users\\14435\\anaconda3\\envs\\tensorflow\\lib\\site-packages\\tensorflow_core\\_api\\v2\\audio\\__init__.py\", line 10, in <module>\n",
      "    from tensorflow.python.ops.gen_audio_ops import decode_wav\n",
      "  File \"C:\\Users\\14435\\anaconda3\\envs\\tensorflow\\lib\\site-packages\\tensorflow_core\\python\\ops\\gen_audio_ops.py\", line 9, in <module>\n",
      "    from tensorflow.python.eager import context as _context\n",
      "  File \"C:\\Users\\14435\\anaconda3\\envs\\tensorflow\\lib\\site-packages\\tensorflow_core\\python\\eager\\context.py\", line 29, in <module>\n",
      "    from tensorflow.core.protobuf import config_pb2\n",
      "  File \"C:\\Users\\14435\\anaconda3\\envs\\tensorflow\\lib\\site-packages\\tensorflow_core\\core\\protobuf\\config_pb2.py\", line 16, in <module>\n",
      "    from tensorflow.core.framework import cost_graph_pb2 as tensorflow_dot_core_dot_framework_dot_cost__graph__pb2\n",
      "  File \"C:\\Users\\14435\\anaconda3\\envs\\tensorflow\\lib\\site-packages\\tensorflow_core\\core\\framework\\cost_graph_pb2.py\", line 16, in <module>\n",
      "    from tensorflow.core.framework import tensor_shape_pb2 as tensorflow_dot_core_dot_framework_dot_tensor__shape__pb2\n",
      "  File \"C:\\Users\\14435\\anaconda3\\envs\\tensorflow\\lib\\site-packages\\tensorflow_core\\core\\framework\\tensor_shape_pb2.py\", line 42, in <module>\n",
      "    serialized_options=None, file=DESCRIPTOR),\n",
      "  File \"C:\\Users\\14435\\anaconda3\\envs\\tensorflow\\lib\\site-packages\\google\\protobuf\\descriptor.py\", line 561, in __new__\n",
      "    _message.Message._CheckCalledFromGeneratedFile()\n",
      "TypeError: Descriptors cannot not be created directly.\n",
      "If this call came from a _pb2.py file, your generated code is out of date and must be regenerated with protoc >= 3.19.0.\n",
      "If you cannot immediately regenerate your protos, some other possible workarounds are:\n",
      " 1. Downgrade the protobuf package to 3.20.x or lower.\n",
      " 2. Set PROTOCOL_BUFFERS_PYTHON_IMPLEMENTATION=python (but this will use pure-Python parsing and will be much slower).\n",
      "\n",
      "More information: https://developers.google.com/protocol-buffers/docs/news/2022-05-06#python-updates\n",
      "Traceback (most recent call last):\n",
      "  File \"C:\\Users\\14435\\anaconda3\\envs\\tensorflow\\lib\\site-packages\\IPython\\core\\interactiveshell.py\", line 3457, in run_code\n",
      "    exec(code_obj, self.user_global_ns, self.user_ns)\n",
      "  File \"C:\\Users\\14435\\AppData\\Local\\Temp\\ipykernel_194552\\2246566909.py\", line 3, in <module>\n",
      "    from tensorflow.keras import layers, models, utils\n",
      "  File \"C:\\Users\\14435\\anaconda3\\envs\\tensorflow\\lib\\site-packages\\tensorflow\\__init__.py\", line 101, in <module>\n",
      "    from tensorflow_core import *\n",
      "  File \"C:\\Users\\14435\\anaconda3\\envs\\tensorflow\\lib\\site-packages\\tensorflow_core\\__init__.py\", line 40, in <module>\n",
      "    from tensorflow.python.tools import module_util as _module_util\n",
      "  File \"<frozen importlib._bootstrap>\", line 983, in _find_and_load\n",
      "  File \"<frozen importlib._bootstrap>\", line 959, in _find_and_load_unlocked\n",
      "  File \"C:\\Users\\14435\\anaconda3\\envs\\tensorflow\\lib\\site-packages\\tensorflow\\__init__.py\", line 50, in __getattr__\n",
      "    module = self._load()\n",
      "  File \"C:\\Users\\14435\\anaconda3\\envs\\tensorflow\\lib\\site-packages\\tensorflow\\__init__.py\", line 44, in _load\n",
      "    module = _importlib.import_module(self.__name__)\n",
      "  File \"C:\\Users\\14435\\anaconda3\\envs\\tensorflow\\lib\\importlib\\__init__.py\", line 127, in import_module\n",
      "    return _bootstrap._gcd_import(name[level:], package, level)\n",
      "  File \"C:\\Users\\14435\\anaconda3\\envs\\tensorflow\\lib\\site-packages\\tensorflow_core\\python\\__init__.py\", line 64, in <module>\n",
      "    from tensorflow.core.framework.graph_pb2 import *\n",
      "  File \"C:\\Users\\14435\\anaconda3\\envs\\tensorflow\\lib\\site-packages\\tensorflow_core\\core\\framework\\graph_pb2.py\", line 16, in <module>\n",
      "    from tensorflow.core.framework import node_def_pb2 as tensorflow_dot_core_dot_framework_dot_node__def__pb2\n",
      "  File \"C:\\Users\\14435\\anaconda3\\envs\\tensorflow\\lib\\site-packages\\tensorflow_core\\core\\framework\\node_def_pb2.py\", line 16, in <module>\n",
      "    from tensorflow.core.framework import attr_value_pb2 as tensorflow_dot_core_dot_framework_dot_attr__value__pb2\n",
      "  File \"C:\\Users\\14435\\anaconda3\\envs\\tensorflow\\lib\\site-packages\\tensorflow_core\\core\\framework\\attr_value_pb2.py\", line 16, in <module>\n",
      "    from tensorflow.core.framework import tensor_pb2 as tensorflow_dot_core_dot_framework_dot_tensor__pb2\n",
      "  File \"C:\\Users\\14435\\anaconda3\\envs\\tensorflow\\lib\\site-packages\\tensorflow_core\\core\\framework\\tensor_pb2.py\", line 16, in <module>\n",
      "    from tensorflow.core.framework import resource_handle_pb2 as tensorflow_dot_core_dot_framework_dot_resource__handle__pb2\n",
      "  File \"C:\\Users\\14435\\anaconda3\\envs\\tensorflow\\lib\\site-packages\\tensorflow_core\\core\\framework\\resource_handle_pb2.py\", line 16, in <module>\n",
      "    from tensorflow.core.framework import tensor_shape_pb2 as tensorflow_dot_core_dot_framework_dot_tensor__shape__pb2\n",
      "  File \"C:\\Users\\14435\\anaconda3\\envs\\tensorflow\\lib\\site-packages\\tensorflow_core\\core\\framework\\tensor_shape_pb2.py\", line 42, in <module>\n",
      "    serialized_options=None, file=DESCRIPTOR),\n",
      "  File \"C:\\Users\\14435\\anaconda3\\envs\\tensorflow\\lib\\site-packages\\google\\protobuf\\descriptor.py\", line 561, in __new__\n",
      "    _message.Message._CheckCalledFromGeneratedFile()\n",
      "TypeError: Descriptors cannot not be created directly.\n",
      "If this call came from a _pb2.py file, your generated code is out of date and must be regenerated with protoc >= 3.19.0.\n",
      "If you cannot immediately regenerate your protos, some other possible workarounds are:\n",
      " 1. Downgrade the protobuf package to 3.20.x or lower.\n",
      " 2. Set PROTOCOL_BUFFERS_PYTHON_IMPLEMENTATION=python (but this will use pure-Python parsing and will be much slower).\n",
      "\n",
      "More information: https://developers.google.com/protocol-buffers/docs/news/2022-05-06#python-updates\n",
      "\n",
      "During handling of the above exception, another exception occurred:\n",
      "\n",
      "Traceback (most recent call last):\n",
      "  File \"C:\\Users\\14435\\anaconda3\\envs\\tensorflow\\lib\\site-packages\\IPython\\core\\interactiveshell.py\", line 2077, in showtraceback\n",
      "    stb = value._render_traceback_()\n",
      "AttributeError: 'TypeError' object has no attribute '_render_traceback_'\n",
      "\n",
      "During handling of the above exception, another exception occurred:\n",
      "\n",
      "Traceback (most recent call last):\n",
      "  File \"C:\\Users\\14435\\anaconda3\\envs\\tensorflow\\lib\\site-packages\\IPython\\core\\interactiveshell.py\", line 3377, in run_ast_nodes\n",
      "    if (await self.run_code(code, result,  async_=asy)):\n",
      "  File \"C:\\Users\\14435\\anaconda3\\envs\\tensorflow\\lib\\site-packages\\IPython\\core\\interactiveshell.py\", line 3474, in run_code\n",
      "    self.showtraceback(running_compiled_code=True)\n",
      "  File \"C:\\Users\\14435\\anaconda3\\envs\\tensorflow\\lib\\site-packages\\IPython\\core\\interactiveshell.py\", line 2080, in showtraceback\n",
      "    value, tb, tb_offset=tb_offset)\n",
      "  File \"C:\\Users\\14435\\anaconda3\\envs\\tensorflow\\lib\\site-packages\\IPython\\core\\ultratb.py\", line 1368, in structured_traceback\n",
      "    self, etype, value, tb, tb_offset, number_of_lines_of_context)\n",
      "  File \"C:\\Users\\14435\\anaconda3\\envs\\tensorflow\\lib\\site-packages\\IPython\\core\\ultratb.py\", line 1268, in structured_traceback\n",
      "    self, etype, value, tb, tb_offset, number_of_lines_of_context\n",
      "  File \"C:\\Users\\14435\\anaconda3\\envs\\tensorflow\\lib\\site-packages\\IPython\\core\\ultratb.py\", line 1125, in structured_traceback\n",
      "    tb_offset)\n",
      "  File \"C:\\Users\\14435\\anaconda3\\envs\\tensorflow\\lib\\site-packages\\IPython\\core\\ultratb.py\", line 1082, in format_exception_as_a_whole\n",
      "    last_unique, recursion_repeat = find_recursion(orig_etype, evalue, records)\n",
      "  File \"C:\\Users\\14435\\anaconda3\\envs\\tensorflow\\lib\\site-packages\\IPython\\core\\ultratb.py\", line 382, in find_recursion\n",
      "    return len(records), 0\n",
      "TypeError: object of type 'NoneType' has no len()\n",
      "\n",
      "During handling of the above exception, another exception occurred:\n",
      "\n",
      "Traceback (most recent call last):\n",
      "  File \"C:\\Users\\14435\\anaconda3\\envs\\tensorflow\\lib\\site-packages\\IPython\\core\\interactiveshell.py\", line 2077, in showtraceback\n",
      "    stb = value._render_traceback_()\n",
      "AttributeError: 'TypeError' object has no attribute '_render_traceback_'\n",
      "\n",
      "During handling of the above exception, another exception occurred:\n",
      "\n",
      "Traceback (most recent call last):\n",
      "  File \"C:\\Users\\14435\\anaconda3\\envs\\tensorflow\\lib\\site-packages\\IPython\\core\\interactiveshell.py\", line 2960, in _run_cell\n",
      "    return runner(coro)\n",
      "  File \"C:\\Users\\14435\\anaconda3\\envs\\tensorflow\\lib\\site-packages\\IPython\\core\\async_helpers.py\", line 78, in _pseudo_sync_runner\n",
      "    coro.send(None)\n",
      "  File \"C:\\Users\\14435\\anaconda3\\envs\\tensorflow\\lib\\site-packages\\IPython\\core\\interactiveshell.py\", line 3186, in run_cell_async\n",
      "    interactivity=interactivity, compiler=compiler, result=result)\n",
      "  File \"C:\\Users\\14435\\anaconda3\\envs\\tensorflow\\lib\\site-packages\\IPython\\core\\interactiveshell.py\", line 3396, in run_ast_nodes\n",
      "    self.showtraceback()\n",
      "  File \"C:\\Users\\14435\\anaconda3\\envs\\tensorflow\\lib\\site-packages\\IPython\\core\\interactiveshell.py\", line 2080, in showtraceback\n",
      "    value, tb, tb_offset=tb_offset)\n",
      "  File \"C:\\Users\\14435\\anaconda3\\envs\\tensorflow\\lib\\site-packages\\IPython\\core\\ultratb.py\", line 1368, in structured_traceback\n",
      "    self, etype, value, tb, tb_offset, number_of_lines_of_context)\n",
      "  File \"C:\\Users\\14435\\anaconda3\\envs\\tensorflow\\lib\\site-packages\\IPython\\core\\ultratb.py\", line 1268, in structured_traceback\n",
      "    self, etype, value, tb, tb_offset, number_of_lines_of_context\n",
      "  File \"C:\\Users\\14435\\anaconda3\\envs\\tensorflow\\lib\\site-packages\\IPython\\core\\ultratb.py\", line 1143, in structured_traceback\n",
      "    chained_exceptions_tb_offset)\n",
      "  File \"C:\\Users\\14435\\anaconda3\\envs\\tensorflow\\lib\\site-packages\\IPython\\core\\ultratb.py\", line 1082, in format_exception_as_a_whole\n",
      "    last_unique, recursion_repeat = find_recursion(orig_etype, evalue, records)\n",
      "  File \"C:\\Users\\14435\\anaconda3\\envs\\tensorflow\\lib\\site-packages\\IPython\\core\\ultratb.py\", line 382, in find_recursion\n",
      "    return len(records), 0\n",
      "TypeError: object of type 'NoneType' has no len()\n",
      "\n",
      "During handling of the above exception, another exception occurred:\n",
      "\n",
      "Traceback (most recent call last):\n",
      "  File \"C:\\Users\\14435\\anaconda3\\envs\\tensorflow\\lib\\site-packages\\IPython\\core\\interactiveshell.py\", line 2077, in showtraceback\n",
      "    stb = value._render_traceback_()\n",
      "AttributeError: 'TypeError' object has no attribute '_render_traceback_'\n",
      "\n",
      "During handling of the above exception, another exception occurred:\n",
      "\n",
      "Traceback (most recent call last):\n",
      "  File \"C:\\Users\\14435\\anaconda3\\envs\\tensorflow\\lib\\site-packages\\IPython\\core\\ultratb.py\", line 1101, in get_records\n",
      "    return _fixed_getinnerframes(etb, number_of_lines_of_context, tb_offset)\n",
      "  File \"C:\\Users\\14435\\anaconda3\\envs\\tensorflow\\lib\\site-packages\\IPython\\core\\ultratb.py\", line 248, in wrapped\n",
      "    return f(*args, **kwargs)\n",
      "  File \"C:\\Users\\14435\\anaconda3\\envs\\tensorflow\\lib\\site-packages\\IPython\\core\\ultratb.py\", line 281, in _fixed_getinnerframes\n",
      "    records = fix_frame_records_filenames(inspect.getinnerframes(etb, context))\n",
      "  File \"C:\\Users\\14435\\anaconda3\\envs\\tensorflow\\lib\\inspect.py\", line 1502, in getinnerframes\n",
      "    frameinfo = (tb.tb_frame,) + getframeinfo(tb, context)\n",
      "  File \"C:\\Users\\14435\\anaconda3\\envs\\tensorflow\\lib\\inspect.py\", line 1460, in getframeinfo\n",
      "    filename = getsourcefile(frame) or getfile(frame)\n",
      "  File \"C:\\Users\\14435\\anaconda3\\envs\\tensorflow\\lib\\inspect.py\", line 696, in getsourcefile\n",
      "    if getattr(getmodule(object, filename), '__loader__', None) is not None:\n",
      "  File \"C:\\Users\\14435\\anaconda3\\envs\\tensorflow\\lib\\inspect.py\", line 733, in getmodule\n",
      "    if ismodule(module) and hasattr(module, '__file__'):\n",
      "  File \"C:\\Users\\14435\\anaconda3\\envs\\tensorflow\\lib\\site-packages\\tensorflow\\__init__.py\", line 50, in __getattr__\n",
      "    module = self._load()\n",
      "  File \"C:\\Users\\14435\\anaconda3\\envs\\tensorflow\\lib\\site-packages\\tensorflow\\__init__.py\", line 44, in _load\n",
      "    module = _importlib.import_module(self.__name__)\n",
      "  File \"C:\\Users\\14435\\anaconda3\\envs\\tensorflow\\lib\\importlib\\__init__.py\", line 127, in import_module\n",
      "    return _bootstrap._gcd_import(name[level:], package, level)\n",
      "  File \"<frozen importlib._bootstrap>\", line 1006, in _gcd_import\n",
      "  File \"<frozen importlib._bootstrap>\", line 983, in _find_and_load\n",
      "  File \"<frozen importlib._bootstrap>\", line 953, in _find_and_load_unlocked\n",
      "  File \"<frozen importlib._bootstrap>\", line 219, in _call_with_frames_removed\n",
      "  File \"<frozen importlib._bootstrap>\", line 1006, in _gcd_import\n",
      "  File \"<frozen importlib._bootstrap>\", line 983, in _find_and_load\n",
      "  File \"<frozen importlib._bootstrap>\", line 967, in _find_and_load_unlocked\n",
      "  File \"<frozen importlib._bootstrap>\", line 677, in _load_unlocked\n",
      "  File \"<frozen importlib._bootstrap_external>\", line 728, in exec_module\n",
      "  File \"<frozen importlib._bootstrap>\", line 219, in _call_with_frames_removed\n",
      "  File \"C:\\Users\\14435\\anaconda3\\envs\\tensorflow\\lib\\site-packages\\tensorflow_core\\__init__.py\", line 42, in <module>\n",
      "    from . _api.v2 import audio\n",
      "  File \"C:\\Users\\14435\\anaconda3\\envs\\tensorflow\\lib\\site-packages\\tensorflow_core\\_api\\v2\\audio\\__init__.py\", line 10, in <module>\n",
      "    from tensorflow.python.ops.gen_audio_ops import decode_wav\n",
      "  File \"C:\\Users\\14435\\anaconda3\\envs\\tensorflow\\lib\\site-packages\\tensorflow_core\\python\\ops\\gen_audio_ops.py\", line 9, in <module>\n",
      "    from tensorflow.python.eager import context as _context\n",
      "  File \"C:\\Users\\14435\\anaconda3\\envs\\tensorflow\\lib\\site-packages\\tensorflow_core\\python\\eager\\context.py\", line 29, in <module>\n",
      "    from tensorflow.core.protobuf import config_pb2\n",
      "  File \"C:\\Users\\14435\\anaconda3\\envs\\tensorflow\\lib\\site-packages\\tensorflow_core\\core\\protobuf\\config_pb2.py\", line 16, in <module>\n",
      "    from tensorflow.core.framework import cost_graph_pb2 as tensorflow_dot_core_dot_framework_dot_cost__graph__pb2\n",
      "  File \"C:\\Users\\14435\\anaconda3\\envs\\tensorflow\\lib\\site-packages\\tensorflow_core\\core\\framework\\cost_graph_pb2.py\", line 16, in <module>\n",
      "    from tensorflow.core.framework import tensor_shape_pb2 as tensorflow_dot_core_dot_framework_dot_tensor__shape__pb2\n",
      "  File \"C:\\Users\\14435\\anaconda3\\envs\\tensorflow\\lib\\site-packages\\tensorflow_core\\core\\framework\\tensor_shape_pb2.py\", line 42, in <module>\n",
      "    serialized_options=None, file=DESCRIPTOR),\n",
      "  File \"C:\\Users\\14435\\anaconda3\\envs\\tensorflow\\lib\\site-packages\\google\\protobuf\\descriptor.py\", line 561, in __new__\n",
      "    _message.Message._CheckCalledFromGeneratedFile()\n",
      "TypeError: Descriptors cannot not be created directly.\n",
      "If this call came from a _pb2.py file, your generated code is out of date and must be regenerated with protoc >= 3.19.0.\n",
      "If you cannot immediately regenerate your protos, some other possible workarounds are:\n",
      " 1. Downgrade the protobuf package to 3.20.x or lower.\n",
      " 2. Set PROTOCOL_BUFFERS_PYTHON_IMPLEMENTATION=python (but this will use pure-Python parsing and will be much slower).\n",
      "\n",
      "More information: https://developers.google.com/protocol-buffers/docs/news/2022-05-06#python-updates\n"
     ]
    }
   ],
   "source": [
    "import numpy as np\n",
    "import librosa\n",
    "from tensorflow.keras import layers, models, utils\n",
    "import tensorflow as tf\n",
    "from tensorflow import keras\n",
    "\n",
    "\n",
    "\n",
    "\n",
    "# Function to extract MFCC features from audio files\n",
    "def extract_features(file_path, mfcc=True, chroma=True, mel=True,sr=22050):\n",
    "    audio_data, _ = librosa.load(file_path)  # Load audio data directly without a context manager\n",
    "    features = []\n",
    "    if mfcc:\n",
    "        mfccs = np.mean(librosa.feature.mfcc(y=audio_data, sr=sr, n_mfcc=13), axis=1)\n",
    "        features.extend(mfccs)\n",
    "    if chroma:\n",
    "        chroma = np.mean(librosa.feature.chroma_stft(y=audio_data, sr=sr), axis=1)\n",
    "        features.extend(chroma)\n",
    "    if mel:\n",
    "        mel = np.mean(librosa.feature.melspectrogram(y=audio_data, sr=sr), axis=1)\n",
    "        features.extend(mel)\n",
    "    return features\n",
    "\n",
    "\n",
    "\n",
    "if __name__ == '__main__':\n",
    "\n",
    "    sr=22050\n",
    "    class_names = [\"cyhh\",\"haoyu\",\"stranger\"]\n",
    "    # Load the model\n",
    "    model = tf.keras.models.load_model('speaker_recognition_model')\n",
    "    # preprocessing\n",
    "    test_feature= extract_features(\"test_audio/test.wav\", mfcc=True, chroma=True, mel=True,sr=22050)\n",
    "    # test_feature= extract_features(\"audio_files/haoyu_audio_70.wav\", mfcc=True, chroma=True, mel=True,sr=22050)\n",
    "    print(len(test_feature))\n",
    "    test_feature= np.array(test_feature)\n",
    "    # print(test_feature.shape)\n",
    "    test_feature= test_feature.reshape(1,153,1)\n",
    "    # print(test_feature.shape)\n",
    "\n",
    "    # Make prediction\n",
    "\n",
    "    predictions = model.predict(test_feature)\n",
    "    print(predictions)\n",
    "    # Post-process predictions (e.g., choose the class with the highest probability)\n",
    "    predicted_label = np.argmax(predictions)\n",
    "\n",
    "    print(\"Predicted label:\", class_names[predicted_label])"
   ]
  },
  {
   "cell_type": "code",
   "execution_count": 2,
   "id": "255cb16e",
   "metadata": {},
   "outputs": [
    {
     "name": "stdout",
     "output_type": "stream",
     "text": [
      "Name: protobuf\n",
      "Version: 4.24.4\n",
      "Summary: \n",
      "Home-page: https://developers.google.com/protocol-buffers/\n",
      "Author: protobuf@googlegroups.com\n",
      "Author-email: protobuf@googlegroups.com\n",
      "License: 3-Clause BSD License\n",
      "Location: c:\\users\\14435\\anaconda3\\envs\\tensorflow\\lib\\site-packages\n",
      "Requires: \n",
      "Required-by: google-api-core, googleapis-common-protos, proto-plus, tensorboard, tensorflow\n",
      "Note: you may need to restart the kernel to use updated packages.\n"
     ]
    }
   ],
   "source": [
    "pip show protobuf"
   ]
  },
  {
   "cell_type": "code",
   "execution_count": 11,
   "id": "4a519696",
   "metadata": {},
   "outputs": [
    {
     "name": "stdout",
     "output_type": "stream",
     "text": [
      "Collecting tensorflow==2.1.0\n",
      "  Downloading tensorflow-2.1.0-cp37-cp37m-win_amd64.whl (355.8 MB)\n",
      "     -------------------------------------- 355.8/355.8 MB 3.6 MB/s eta 0:00:00\n",
      "Requirement already satisfied: six>=1.12.0 in c:\\users\\14435\\anaconda3\\envs\\tensorflow\\lib\\site-packages (from tensorflow==2.1.0) (1.15.0)\n",
      "Requirement already satisfied: wheel>=0.26 in c:\\users\\14435\\anaconda3\\envs\\tensorflow\\lib\\site-packages (from tensorflow==2.1.0) (0.38.4)\n",
      "Collecting scipy==1.4.1\n",
      "  Downloading scipy-1.4.1-cp37-cp37m-win_amd64.whl (30.9 MB)\n",
      "     --------------------------------------- 30.9/30.9 MB 12.6 MB/s eta 0:00:00\n",
      "Requirement already satisfied: absl-py>=0.7.0 in c:\\users\\14435\\anaconda3\\envs\\tensorflow\\lib\\site-packages (from tensorflow==2.1.0) (0.15.0)\n",
      "Collecting tensorflow-estimator<2.2.0,>=2.1.0rc0\n",
      "  Downloading tensorflow_estimator-2.1.0-py2.py3-none-any.whl (448 kB)\n",
      "     ------------------------------------- 449.0/449.0 kB 13.7 MB/s eta 0:00:00\n",
      "Collecting gast==0.2.2\n",
      "  Downloading gast-0.2.2.tar.gz (10 kB)\n",
      "  Preparing metadata (setup.py): started\n",
      "  Preparing metadata (setup.py): finished with status 'done'\n",
      "Requirement already satisfied: keras-applications>=1.0.8 in c:\\users\\14435\\anaconda3\\envs\\tensorflow\\lib\\site-packages (from tensorflow==2.1.0) (1.0.8)\n",
      "Requirement already satisfied: protobuf>=3.8.0 in c:\\users\\14435\\anaconda3\\envs\\tensorflow\\lib\\site-packages (from tensorflow==2.1.0) (4.24.4)\n",
      "Requirement already satisfied: termcolor>=1.1.0 in c:\\users\\14435\\anaconda3\\envs\\tensorflow\\lib\\site-packages (from tensorflow==2.1.0) (1.1.0)\n",
      "Requirement already satisfied: numpy<2.0,>=1.16.0 in c:\\users\\14435\\anaconda3\\envs\\tensorflow\\lib\\site-packages (from tensorflow==2.1.0) (1.19.2)\n",
      "Requirement already satisfied: wrapt>=1.11.1 in c:\\users\\14435\\anaconda3\\envs\\tensorflow\\lib\\site-packages (from tensorflow==2.1.0) (1.12.1)\n",
      "Requirement already satisfied: astor>=0.6.0 in c:\\users\\14435\\anaconda3\\envs\\tensorflow\\lib\\site-packages (from tensorflow==2.1.0) (0.8.1)\n",
      "Requirement already satisfied: google-pasta>=0.1.6 in c:\\users\\14435\\anaconda3\\envs\\tensorflow\\lib\\site-packages (from tensorflow==2.1.0) (0.2.0)\n",
      "Requirement already satisfied: opt-einsum>=2.3.2 in c:\\users\\14435\\anaconda3\\envs\\tensorflow\\lib\\site-packages (from tensorflow==2.1.0) (3.3.0)\n",
      "Collecting tensorboard<2.2.0,>=2.1.0\n",
      "  Downloading tensorboard-2.1.1-py3-none-any.whl (3.8 MB)\n",
      "Note: you may need to restart the kernel to use updated packages.\n"
     ]
    },
    {
     "name": "stderr",
     "output_type": "stream",
     "text": [
      "ERROR: pip's dependency resolver does not currently take into account all the packages that are installed. This behaviour is the source of the following dependency conflicts.\n",
      "librosa 0.10.1 requires numpy!=1.22.0,!=1.22.1,!=1.22.2,>=1.20.3, but you have numpy 1.19.2 which is incompatible.\n",
      "librosa 0.10.1 requires typing-extensions>=4.1.1, but you have typing-extensions 3.7.4.3 which is incompatible.\n",
      "google-api-core 2.18.0 requires google-auth<3.0.dev0,>=2.14.1, but you have google-auth 1.35.0 which is incompatible.\n"
     ]
    },
    {
     "name": "stdout",
     "output_type": "stream",
     "text": [
      "     ---------------------------------------- 3.8/3.8 MB 13.7 MB/s eta 0:00:00\n",
      "Requirement already satisfied: grpcio>=1.8.6 in c:\\users\\14435\\anaconda3\\envs\\tensorflow\\lib\\site-packages (from tensorflow==2.1.0) (1.42.0)\n",
      "Requirement already satisfied: keras-preprocessing>=1.1.0 in c:\\users\\14435\\anaconda3\\envs\\tensorflow\\lib\\site-packages (from tensorflow==2.1.0) (1.1.2)\n",
      "Requirement already satisfied: h5py in c:\\users\\14435\\anaconda3\\envs\\tensorflow\\lib\\site-packages (from keras-applications>=1.0.8->tensorflow==2.1.0) (3.1.0)\n",
      "Requirement already satisfied: markdown>=2.6.8 in c:\\users\\14435\\anaconda3\\envs\\tensorflow\\lib\\site-packages (from tensorboard<2.2.0,>=2.1.0->tensorflow==2.1.0) (3.4.1)\n",
      "Requirement already satisfied: google-auth-oauthlib<0.5,>=0.4.1 in c:\\users\\14435\\anaconda3\\envs\\tensorflow\\lib\\site-packages (from tensorboard<2.2.0,>=2.1.0->tensorflow==2.1.0) (0.4.4)\n",
      "Requirement already satisfied: werkzeug>=0.11.15 in c:\\users\\14435\\anaconda3\\envs\\tensorflow\\lib\\site-packages (from tensorboard<2.2.0,>=2.1.0->tensorflow==2.1.0) (0.16.1)\n",
      "Requirement already satisfied: requests<3,>=2.21.0 in c:\\users\\14435\\anaconda3\\envs\\tensorflow\\lib\\site-packages (from tensorboard<2.2.0,>=2.1.0->tensorflow==2.1.0) (2.28.1)\n",
      "Collecting google-auth<2,>=1.6.3\n",
      "  Downloading google_auth-1.35.0-py2.py3-none-any.whl (152 kB)\n",
      "     -------------------------------------- 152.9/152.9 kB 9.5 MB/s eta 0:00:00\n",
      "Requirement already satisfied: setuptools>=41.0.0 in c:\\users\\14435\\anaconda3\\envs\\tensorflow\\lib\\site-packages (from tensorboard<2.2.0,>=2.1.0->tensorflow==2.1.0) (65.6.3)\n",
      "Requirement already satisfied: pyasn1-modules>=0.2.1 in c:\\users\\14435\\anaconda3\\envs\\tensorflow\\lib\\site-packages (from google-auth<2,>=1.6.3->tensorboard<2.2.0,>=2.1.0->tensorflow==2.1.0) (0.2.8)\n",
      "Requirement already satisfied: cachetools<5.0,>=2.0.0 in c:\\users\\14435\\anaconda3\\envs\\tensorflow\\lib\\site-packages (from google-auth<2,>=1.6.3->tensorboard<2.2.0,>=2.1.0->tensorflow==2.1.0) (4.2.2)\n",
      "Requirement already satisfied: rsa<5,>=3.1.4 in c:\\users\\14435\\anaconda3\\envs\\tensorflow\\lib\\site-packages (from google-auth<2,>=1.6.3->tensorboard<2.2.0,>=2.1.0->tensorflow==2.1.0) (4.7.2)\n",
      "Requirement already satisfied: requests-oauthlib>=0.7.0 in c:\\users\\14435\\anaconda3\\envs\\tensorflow\\lib\\site-packages (from google-auth-oauthlib<0.5,>=0.4.1->tensorboard<2.2.0,>=2.1.0->tensorflow==2.1.0) (1.3.0)\n",
      "Requirement already satisfied: importlib-metadata>=4.4 in c:\\users\\14435\\anaconda3\\envs\\tensorflow\\lib\\site-packages (from markdown>=2.6.8->tensorboard<2.2.0,>=2.1.0->tensorflow==2.1.0) (4.11.3)\n",
      "Requirement already satisfied: urllib3<1.27,>=1.21.1 in c:\\users\\14435\\anaconda3\\envs\\tensorflow\\lib\\site-packages (from requests<3,>=2.21.0->tensorboard<2.2.0,>=2.1.0->tensorflow==2.1.0) (1.26.14)\n",
      "Requirement already satisfied: charset-normalizer<3,>=2 in c:\\users\\14435\\anaconda3\\envs\\tensorflow\\lib\\site-packages (from requests<3,>=2.21.0->tensorboard<2.2.0,>=2.1.0->tensorflow==2.1.0) (2.0.4)\n",
      "Requirement already satisfied: idna<4,>=2.5 in c:\\users\\14435\\anaconda3\\envs\\tensorflow\\lib\\site-packages (from requests<3,>=2.21.0->tensorboard<2.2.0,>=2.1.0->tensorflow==2.1.0) (3.4)\n",
      "Requirement already satisfied: certifi>=2017.4.17 in c:\\users\\14435\\anaconda3\\envs\\tensorflow\\lib\\site-packages (from requests<3,>=2.21.0->tensorboard<2.2.0,>=2.1.0->tensorflow==2.1.0) (2022.12.7)\n",
      "Requirement already satisfied: cached-property in c:\\users\\14435\\anaconda3\\envs\\tensorflow\\lib\\site-packages (from h5py->keras-applications>=1.0.8->tensorflow==2.1.0) (1.5.2)\n",
      "Requirement already satisfied: zipp>=0.5 in c:\\users\\14435\\anaconda3\\envs\\tensorflow\\lib\\site-packages (from importlib-metadata>=4.4->markdown>=2.6.8->tensorboard<2.2.0,>=2.1.0->tensorflow==2.1.0) (3.11.0)\n",
      "Requirement already satisfied: typing-extensions>=3.6.4 in c:\\users\\14435\\anaconda3\\envs\\tensorflow\\lib\\site-packages (from importlib-metadata>=4.4->markdown>=2.6.8->tensorboard<2.2.0,>=2.1.0->tensorflow==2.1.0) (3.7.4.3)\n",
      "Requirement already satisfied: pyasn1<0.5.0,>=0.4.6 in c:\\users\\14435\\anaconda3\\envs\\tensorflow\\lib\\site-packages (from pyasn1-modules>=0.2.1->google-auth<2,>=1.6.3->tensorboard<2.2.0,>=2.1.0->tensorflow==2.1.0) (0.4.8)\n",
      "Requirement already satisfied: oauthlib>=3.0.0 in c:\\users\\14435\\anaconda3\\envs\\tensorflow\\lib\\site-packages (from requests-oauthlib>=0.7.0->google-auth-oauthlib<0.5,>=0.4.1->tensorboard<2.2.0,>=2.1.0->tensorflow==2.1.0) (3.2.1)\n",
      "Building wheels for collected packages: gast\n",
      "  Building wheel for gast (setup.py): started\n",
      "  Building wheel for gast (setup.py): finished with status 'done'\n",
      "  Created wheel for gast: filename=gast-0.2.2-py3-none-any.whl size=7549 sha256=1360e453b1b680c2dc8c2a629f5980a0c7e3dfd23c0d1d36cd67708e2aa36b2b\n",
      "  Stored in directory: c:\\users\\14435\\appdata\\local\\pip\\cache\\wheels\\cf\\87\\6f\\3f34218ef184368cec9ee65bdfd65baf117811f0a0ce1263ff\n",
      "Successfully built gast\n",
      "Installing collected packages: tensorflow-estimator, scipy, gast, google-auth, tensorboard, tensorflow\n",
      "  Attempting uninstall: tensorflow-estimator\n",
      "    Found existing installation: tensorflow-estimator 2.15.0\n",
      "    Uninstalling tensorflow-estimator-2.15.0:\n",
      "      Successfully uninstalled tensorflow-estimator-2.15.0\n",
      "  Attempting uninstall: scipy\n",
      "    Found existing installation: scipy 1.7.3\n",
      "    Uninstalling scipy-1.7.3:\n",
      "      Successfully uninstalled scipy-1.7.3\n",
      "  Attempting uninstall: gast\n",
      "    Found existing installation: gast 0.4.0\n",
      "    Uninstalling gast-0.4.0:\n",
      "      Successfully uninstalled gast-0.4.0\n",
      "  Attempting uninstall: google-auth\n",
      "    Found existing installation: google-auth 2.29.0\n",
      "    Uninstalling google-auth-2.29.0:\n",
      "      Successfully uninstalled google-auth-2.29.0\n",
      "  Attempting uninstall: tensorboard\n",
      "    Found existing installation: tensorboard 2.8.0\n",
      "    Uninstalling tensorboard-2.8.0:\n",
      "      Successfully uninstalled tensorboard-2.8.0\n",
      "  Attempting uninstall: tensorflow\n",
      "    Found existing installation: tensorflow 2.6.0\n",
      "    Uninstalling tensorflow-2.6.0:\n",
      "      Successfully uninstalled tensorflow-2.6.0\n",
      "Successfully installed gast-0.2.2 google-auth-1.35.0 scipy-1.4.1 tensorboard-2.1.1 tensorflow-2.1.0 tensorflow-estimator-2.1.0\n"
     ]
    }
   ],
   "source": [
    "pip install tensorflow==2.1.0\n"
   ]
  },
  {
   "cell_type": "code",
   "execution_count": 12,
   "id": "2c5c644f",
   "metadata": {},
   "outputs": [
    {
     "name": "stdout",
     "output_type": "stream",
     "text": [
      "ERROR! Session/line number was not unique in database. History logging moved to new session 128\n",
      "Collecting protobuf==3.20.0\n",
      "  Downloading protobuf-3.20.0-cp37-cp37m-win_amd64.whl (905 kB)\n",
      "     -------------------------------------- 905.1/905.1 kB 9.6 MB/s eta 0:00:00\n",
      "Installing collected packages: protobuf\n",
      "  Attempting uninstall: protobuf\n",
      "    Found existing installation: protobuf 4.24.4\n",
      "    Uninstalling protobuf-4.24.4:\n",
      "      Successfully uninstalled protobuf-4.24.4\n",
      "Note: you may need to restart the kernel to use updated packages.\n"
     ]
    },
    {
     "name": "stderr",
     "output_type": "stream",
     "text": [
      "ERROR: Could not install packages due to an OSError: [WinError 5] Access is denied: 'c:\\\\users\\\\14435\\\\anaconda3\\\\envs\\\\tensorflow\\\\lib\\\\site-packages\\\\google\\\\~upb\\\\_message.cp37-win_amd64.pyd'\n",
      "Consider using the `--user` option or check the permissions.\n",
      "\n"
     ]
    }
   ],
   "source": [
    "pip install --upgrade protobuf==3.20.0\n"
   ]
  },
  {
   "cell_type": "code",
   "execution_count": null,
   "id": "2aba8d8e",
   "metadata": {},
   "outputs": [
    {
     "name": "stderr",
     "output_type": "stream",
     "text": [
      "ERROR:root:Internal Python error in the inspect module.\n",
      "Below is the traceback from this internal error.\n",
      "\n",
      "ERROR:root:Internal Python error in the inspect module.\n",
      "Below is the traceback from this internal error.\n",
      "\n",
      "ERROR:root:Internal Python error in the inspect module.\n",
      "Below is the traceback from this internal error.\n",
      "\n"
     ]
    },
    {
     "name": "stdout",
     "output_type": "stream",
     "text": [
      "Traceback (most recent call last):\n",
      "  File \"C:\\Users\\14435\\anaconda3\\envs\\tensorflow\\lib\\site-packages\\IPython\\core\\interactiveshell.py\", line 3457, in run_code\n",
      "    exec(code_obj, self.user_global_ns, self.user_ns)\n",
      "  File \"C:\\Users\\14435\\AppData\\Local\\Temp\\ipykernel_382640\\3027163026.py\", line 1, in <module>\n",
      "    from tensorflow.keras import layers, models, utils\n",
      "  File \"C:\\Users\\14435\\anaconda3\\envs\\tensorflow\\lib\\site-packages\\tensorflow\\__init__.py\", line 101, in <module>\n",
      "    from tensorflow_core import *\n",
      "  File \"C:\\Users\\14435\\anaconda3\\envs\\tensorflow\\lib\\site-packages\\tensorflow_core\\__init__.py\", line 40, in <module>\n",
      "    from tensorflow.python.tools import module_util as _module_util\n",
      "  File \"<frozen importlib._bootstrap>\", line 983, in _find_and_load\n",
      "  File \"<frozen importlib._bootstrap>\", line 959, in _find_and_load_unlocked\n",
      "  File \"C:\\Users\\14435\\anaconda3\\envs\\tensorflow\\lib\\site-packages\\tensorflow\\__init__.py\", line 50, in __getattr__\n",
      "    module = self._load()\n",
      "  File \"C:\\Users\\14435\\anaconda3\\envs\\tensorflow\\lib\\site-packages\\tensorflow\\__init__.py\", line 44, in _load\n",
      "    module = _importlib.import_module(self.__name__)\n",
      "  File \"C:\\Users\\14435\\anaconda3\\envs\\tensorflow\\lib\\importlib\\__init__.py\", line 127, in import_module\n",
      "    return _bootstrap._gcd_import(name[level:], package, level)\n",
      "  File \"C:\\Users\\14435\\anaconda3\\envs\\tensorflow\\lib\\site-packages\\tensorflow_core\\python\\__init__.py\", line 64, in <module>\n",
      "    from tensorflow.core.framework.graph_pb2 import *\n",
      "  File \"C:\\Users\\14435\\anaconda3\\envs\\tensorflow\\lib\\site-packages\\tensorflow_core\\core\\framework\\graph_pb2.py\", line 16, in <module>\n",
      "    from tensorflow.core.framework import node_def_pb2 as tensorflow_dot_core_dot_framework_dot_node__def__pb2\n",
      "  File \"C:\\Users\\14435\\anaconda3\\envs\\tensorflow\\lib\\site-packages\\tensorflow_core\\core\\framework\\node_def_pb2.py\", line 16, in <module>\n",
      "    from tensorflow.core.framework import attr_value_pb2 as tensorflow_dot_core_dot_framework_dot_attr__value__pb2\n",
      "  File \"C:\\Users\\14435\\anaconda3\\envs\\tensorflow\\lib\\site-packages\\tensorflow_core\\core\\framework\\attr_value_pb2.py\", line 16, in <module>\n",
      "    from tensorflow.core.framework import tensor_pb2 as tensorflow_dot_core_dot_framework_dot_tensor__pb2\n",
      "  File \"C:\\Users\\14435\\anaconda3\\envs\\tensorflow\\lib\\site-packages\\tensorflow_core\\core\\framework\\tensor_pb2.py\", line 16, in <module>\n",
      "    from tensorflow.core.framework import resource_handle_pb2 as tensorflow_dot_core_dot_framework_dot_resource__handle__pb2\n",
      "  File \"C:\\Users\\14435\\anaconda3\\envs\\tensorflow\\lib\\site-packages\\tensorflow_core\\core\\framework\\resource_handle_pb2.py\", line 16, in <module>\n",
      "    from tensorflow.core.framework import tensor_shape_pb2 as tensorflow_dot_core_dot_framework_dot_tensor__shape__pb2\n",
      "  File \"C:\\Users\\14435\\anaconda3\\envs\\tensorflow\\lib\\site-packages\\tensorflow_core\\core\\framework\\tensor_shape_pb2.py\", line 42, in <module>\n",
      "    serialized_options=None, file=DESCRIPTOR),\n",
      "  File \"C:\\Users\\14435\\anaconda3\\envs\\tensorflow\\lib\\site-packages\\google\\protobuf\\descriptor.py\", line 561, in __new__\n",
      "    _message.Message._CheckCalledFromGeneratedFile()\n",
      "TypeError: Descriptors cannot not be created directly.\n",
      "If this call came from a _pb2.py file, your generated code is out of date and must be regenerated with protoc >= 3.19.0.\n",
      "If you cannot immediately regenerate your protos, some other possible workarounds are:\n",
      " 1. Downgrade the protobuf package to 3.20.x or lower.\n",
      " 2. Set PROTOCOL_BUFFERS_PYTHON_IMPLEMENTATION=python (but this will use pure-Python parsing and will be much slower).\n",
      "\n",
      "More information: https://developers.google.com/protocol-buffers/docs/news/2022-05-06#python-updates\n",
      "\n",
      "During handling of the above exception, another exception occurred:\n",
      "\n",
      "Traceback (most recent call last):\n",
      "  File \"C:\\Users\\14435\\anaconda3\\envs\\tensorflow\\lib\\site-packages\\IPython\\core\\interactiveshell.py\", line 2077, in showtraceback\n",
      "    stb = value._render_traceback_()\n",
      "AttributeError: 'TypeError' object has no attribute '_render_traceback_'\n",
      "\n",
      "During handling of the above exception, another exception occurred:\n",
      "\n",
      "Traceback (most recent call last):\n",
      "  File \"C:\\Users\\14435\\anaconda3\\envs\\tensorflow\\lib\\site-packages\\IPython\\core\\ultratb.py\", line 1101, in get_records\n",
      "    return _fixed_getinnerframes(etb, number_of_lines_of_context, tb_offset)\n",
      "  File \"C:\\Users\\14435\\anaconda3\\envs\\tensorflow\\lib\\site-packages\\IPython\\core\\ultratb.py\", line 248, in wrapped\n",
      "    return f(*args, **kwargs)\n",
      "  File \"C:\\Users\\14435\\anaconda3\\envs\\tensorflow\\lib\\site-packages\\IPython\\core\\ultratb.py\", line 281, in _fixed_getinnerframes\n",
      "    records = fix_frame_records_filenames(inspect.getinnerframes(etb, context))\n",
      "  File \"C:\\Users\\14435\\anaconda3\\envs\\tensorflow\\lib\\inspect.py\", line 1502, in getinnerframes\n",
      "    frameinfo = (tb.tb_frame,) + getframeinfo(tb, context)\n",
      "  File \"C:\\Users\\14435\\anaconda3\\envs\\tensorflow\\lib\\inspect.py\", line 1460, in getframeinfo\n",
      "    filename = getsourcefile(frame) or getfile(frame)\n",
      "  File \"C:\\Users\\14435\\anaconda3\\envs\\tensorflow\\lib\\inspect.py\", line 696, in getsourcefile\n",
      "    if getattr(getmodule(object, filename), '__loader__', None) is not None:\n",
      "  File \"C:\\Users\\14435\\anaconda3\\envs\\tensorflow\\lib\\inspect.py\", line 733, in getmodule\n",
      "    if ismodule(module) and hasattr(module, '__file__'):\n",
      "  File \"C:\\Users\\14435\\anaconda3\\envs\\tensorflow\\lib\\site-packages\\tensorflow\\__init__.py\", line 50, in __getattr__\n",
      "    module = self._load()\n",
      "  File \"C:\\Users\\14435\\anaconda3\\envs\\tensorflow\\lib\\site-packages\\tensorflow\\__init__.py\", line 44, in _load\n",
      "    module = _importlib.import_module(self.__name__)\n",
      "  File \"C:\\Users\\14435\\anaconda3\\envs\\tensorflow\\lib\\importlib\\__init__.py\", line 127, in import_module\n",
      "    return _bootstrap._gcd_import(name[level:], package, level)\n",
      "  File \"<frozen importlib._bootstrap>\", line 1006, in _gcd_import\n",
      "  File \"<frozen importlib._bootstrap>\", line 983, in _find_and_load\n",
      "  File \"<frozen importlib._bootstrap>\", line 953, in _find_and_load_unlocked\n",
      "  File \"<frozen importlib._bootstrap>\", line 219, in _call_with_frames_removed\n",
      "  File \"<frozen importlib._bootstrap>\", line 1006, in _gcd_import\n",
      "  File \"<frozen importlib._bootstrap>\", line 983, in _find_and_load\n",
      "  File \"<frozen importlib._bootstrap>\", line 967, in _find_and_load_unlocked\n",
      "  File \"<frozen importlib._bootstrap>\", line 677, in _load_unlocked\n",
      "  File \"<frozen importlib._bootstrap_external>\", line 728, in exec_module\n",
      "  File \"<frozen importlib._bootstrap>\", line 219, in _call_with_frames_removed\n",
      "  File \"C:\\Users\\14435\\anaconda3\\envs\\tensorflow\\lib\\site-packages\\tensorflow_core\\__init__.py\", line 42, in <module>\n",
      "    from . _api.v2 import audio\n",
      "  File \"C:\\Users\\14435\\anaconda3\\envs\\tensorflow\\lib\\site-packages\\tensorflow_core\\_api\\v2\\audio\\__init__.py\", line 10, in <module>\n",
      "    from tensorflow.python.ops.gen_audio_ops import decode_wav\n",
      "  File \"C:\\Users\\14435\\anaconda3\\envs\\tensorflow\\lib\\site-packages\\tensorflow_core\\python\\ops\\gen_audio_ops.py\", line 10, in <module>\n",
      "    from tensorflow.python.eager import context as _context\n",
      "  File \"C:\\Users\\14435\\anaconda3\\envs\\tensorflow\\lib\\site-packages\\tensorflow_core\\python\\eager\\context.py\", line 29, in <module>\n",
      "    from tensorflow.core.protobuf import config_pb2\n",
      "  File \"C:\\Users\\14435\\anaconda3\\envs\\tensorflow\\lib\\site-packages\\tensorflow_core\\core\\protobuf\\config_pb2.py\", line 16, in <module>\n",
      "    from tensorflow.core.framework import cost_graph_pb2 as tensorflow_dot_core_dot_framework_dot_cost__graph__pb2\n",
      "  File \"C:\\Users\\14435\\anaconda3\\envs\\tensorflow\\lib\\site-packages\\tensorflow_core\\core\\framework\\cost_graph_pb2.py\", line 16, in <module>\n",
      "    from tensorflow.core.framework import tensor_shape_pb2 as tensorflow_dot_core_dot_framework_dot_tensor__shape__pb2\n",
      "  File \"C:\\Users\\14435\\anaconda3\\envs\\tensorflow\\lib\\site-packages\\tensorflow_core\\core\\framework\\tensor_shape_pb2.py\", line 42, in <module>\n",
      "    serialized_options=None, file=DESCRIPTOR),\n",
      "  File \"C:\\Users\\14435\\anaconda3\\envs\\tensorflow\\lib\\site-packages\\google\\protobuf\\descriptor.py\", line 561, in __new__\n",
      "    _message.Message._CheckCalledFromGeneratedFile()\n",
      "TypeError: Descriptors cannot not be created directly.\n",
      "If this call came from a _pb2.py file, your generated code is out of date and must be regenerated with protoc >= 3.19.0.\n",
      "If you cannot immediately regenerate your protos, some other possible workarounds are:\n",
      " 1. Downgrade the protobuf package to 3.20.x or lower.\n",
      " 2. Set PROTOCOL_BUFFERS_PYTHON_IMPLEMENTATION=python (but this will use pure-Python parsing and will be much slower).\n",
      "\n",
      "More information: https://developers.google.com/protocol-buffers/docs/news/2022-05-06#python-updates\n",
      "Traceback (most recent call last):\n",
      "  File \"C:\\Users\\14435\\anaconda3\\envs\\tensorflow\\lib\\site-packages\\IPython\\core\\interactiveshell.py\", line 3457, in run_code\n",
      "    exec(code_obj, self.user_global_ns, self.user_ns)\n",
      "  File \"C:\\Users\\14435\\AppData\\Local\\Temp\\ipykernel_382640\\3027163026.py\", line 1, in <module>\n",
      "    from tensorflow.keras import layers, models, utils\n",
      "  File \"C:\\Users\\14435\\anaconda3\\envs\\tensorflow\\lib\\site-packages\\tensorflow\\__init__.py\", line 101, in <module>\n",
      "    from tensorflow_core import *\n",
      "  File \"C:\\Users\\14435\\anaconda3\\envs\\tensorflow\\lib\\site-packages\\tensorflow_core\\__init__.py\", line 40, in <module>\n",
      "    from tensorflow.python.tools import module_util as _module_util\n",
      "  File \"<frozen importlib._bootstrap>\", line 983, in _find_and_load\n",
      "  File \"<frozen importlib._bootstrap>\", line 959, in _find_and_load_unlocked\n",
      "  File \"C:\\Users\\14435\\anaconda3\\envs\\tensorflow\\lib\\site-packages\\tensorflow\\__init__.py\", line 50, in __getattr__\n",
      "    module = self._load()\n",
      "  File \"C:\\Users\\14435\\anaconda3\\envs\\tensorflow\\lib\\site-packages\\tensorflow\\__init__.py\", line 44, in _load\n",
      "    module = _importlib.import_module(self.__name__)\n",
      "  File \"C:\\Users\\14435\\anaconda3\\envs\\tensorflow\\lib\\importlib\\__init__.py\", line 127, in import_module\n",
      "    return _bootstrap._gcd_import(name[level:], package, level)\n",
      "  File \"C:\\Users\\14435\\anaconda3\\envs\\tensorflow\\lib\\site-packages\\tensorflow_core\\python\\__init__.py\", line 64, in <module>\n",
      "    from tensorflow.core.framework.graph_pb2 import *\n",
      "  File \"C:\\Users\\14435\\anaconda3\\envs\\tensorflow\\lib\\site-packages\\tensorflow_core\\core\\framework\\graph_pb2.py\", line 16, in <module>\n",
      "    from tensorflow.core.framework import node_def_pb2 as tensorflow_dot_core_dot_framework_dot_node__def__pb2\n",
      "  File \"C:\\Users\\14435\\anaconda3\\envs\\tensorflow\\lib\\site-packages\\tensorflow_core\\core\\framework\\node_def_pb2.py\", line 16, in <module>\n",
      "    from tensorflow.core.framework import attr_value_pb2 as tensorflow_dot_core_dot_framework_dot_attr__value__pb2\n",
      "  File \"C:\\Users\\14435\\anaconda3\\envs\\tensorflow\\lib\\site-packages\\tensorflow_core\\core\\framework\\attr_value_pb2.py\", line 16, in <module>\n",
      "    from tensorflow.core.framework import tensor_pb2 as tensorflow_dot_core_dot_framework_dot_tensor__pb2\n",
      "  File \"C:\\Users\\14435\\anaconda3\\envs\\tensorflow\\lib\\site-packages\\tensorflow_core\\core\\framework\\tensor_pb2.py\", line 16, in <module>\n",
      "    from tensorflow.core.framework import resource_handle_pb2 as tensorflow_dot_core_dot_framework_dot_resource__handle__pb2\n",
      "  File \"C:\\Users\\14435\\anaconda3\\envs\\tensorflow\\lib\\site-packages\\tensorflow_core\\core\\framework\\resource_handle_pb2.py\", line 16, in <module>\n",
      "    from tensorflow.core.framework import tensor_shape_pb2 as tensorflow_dot_core_dot_framework_dot_tensor__shape__pb2\n",
      "  File \"C:\\Users\\14435\\anaconda3\\envs\\tensorflow\\lib\\site-packages\\tensorflow_core\\core\\framework\\tensor_shape_pb2.py\", line 42, in <module>\n",
      "    serialized_options=None, file=DESCRIPTOR),\n",
      "  File \"C:\\Users\\14435\\anaconda3\\envs\\tensorflow\\lib\\site-packages\\google\\protobuf\\descriptor.py\", line 561, in __new__\n",
      "    _message.Message._CheckCalledFromGeneratedFile()\n",
      "TypeError: Descriptors cannot not be created directly.\n",
      "If this call came from a _pb2.py file, your generated code is out of date and must be regenerated with protoc >= 3.19.0.\n",
      "If you cannot immediately regenerate your protos, some other possible workarounds are:\n",
      " 1. Downgrade the protobuf package to 3.20.x or lower.\n",
      " 2. Set PROTOCOL_BUFFERS_PYTHON_IMPLEMENTATION=python (but this will use pure-Python parsing and will be much slower).\n",
      "\n",
      "More information: https://developers.google.com/protocol-buffers/docs/news/2022-05-06#python-updates\n",
      "\n",
      "During handling of the above exception, another exception occurred:\n",
      "\n",
      "Traceback (most recent call last):\n",
      "  File \"C:\\Users\\14435\\anaconda3\\envs\\tensorflow\\lib\\site-packages\\IPython\\core\\interactiveshell.py\", line 2077, in showtraceback\n",
      "    stb = value._render_traceback_()\n",
      "AttributeError: 'TypeError' object has no attribute '_render_traceback_'\n",
      "\n",
      "During handling of the above exception, another exception occurred:\n",
      "\n",
      "Traceback (most recent call last):\n",
      "  File \"C:\\Users\\14435\\anaconda3\\envs\\tensorflow\\lib\\site-packages\\IPython\\core\\interactiveshell.py\", line 3377, in run_ast_nodes\n",
      "    if (await self.run_code(code, result,  async_=asy)):\n",
      "  File \"C:\\Users\\14435\\anaconda3\\envs\\tensorflow\\lib\\site-packages\\IPython\\core\\interactiveshell.py\", line 3474, in run_code\n",
      "    self.showtraceback(running_compiled_code=True)\n",
      "  File \"C:\\Users\\14435\\anaconda3\\envs\\tensorflow\\lib\\site-packages\\IPython\\core\\interactiveshell.py\", line 2080, in showtraceback\n",
      "    value, tb, tb_offset=tb_offset)\n",
      "  File \"C:\\Users\\14435\\anaconda3\\envs\\tensorflow\\lib\\site-packages\\IPython\\core\\ultratb.py\", line 1368, in structured_traceback\n",
      "    self, etype, value, tb, tb_offset, number_of_lines_of_context)\n",
      "  File \"C:\\Users\\14435\\anaconda3\\envs\\tensorflow\\lib\\site-packages\\IPython\\core\\ultratb.py\", line 1268, in structured_traceback\n",
      "    self, etype, value, tb, tb_offset, number_of_lines_of_context\n",
      "  File \"C:\\Users\\14435\\anaconda3\\envs\\tensorflow\\lib\\site-packages\\IPython\\core\\ultratb.py\", line 1125, in structured_traceback\n",
      "    tb_offset)\n",
      "  File \"C:\\Users\\14435\\anaconda3\\envs\\tensorflow\\lib\\site-packages\\IPython\\core\\ultratb.py\", line 1082, in format_exception_as_a_whole\n",
      "    last_unique, recursion_repeat = find_recursion(orig_etype, evalue, records)\n",
      "  File \"C:\\Users\\14435\\anaconda3\\envs\\tensorflow\\lib\\site-packages\\IPython\\core\\ultratb.py\", line 382, in find_recursion\n",
      "    return len(records), 0\n",
      "TypeError: object of type 'NoneType' has no len()\n",
      "\n",
      "During handling of the above exception, another exception occurred:\n",
      "\n",
      "Traceback (most recent call last):\n",
      "  File \"C:\\Users\\14435\\anaconda3\\envs\\tensorflow\\lib\\site-packages\\IPython\\core\\interactiveshell.py\", line 2077, in showtraceback\n",
      "    stb = value._render_traceback_()\n",
      "AttributeError: 'TypeError' object has no attribute '_render_traceback_'\n",
      "\n",
      "During handling of the above exception, another exception occurred:\n",
      "\n",
      "Traceback (most recent call last):\n",
      "  File \"C:\\Users\\14435\\anaconda3\\envs\\tensorflow\\lib\\site-packages\\IPython\\core\\ultratb.py\", line 1101, in get_records\n",
      "    return _fixed_getinnerframes(etb, number_of_lines_of_context, tb_offset)\n",
      "  File \"C:\\Users\\14435\\anaconda3\\envs\\tensorflow\\lib\\site-packages\\IPython\\core\\ultratb.py\", line 248, in wrapped\n",
      "    return f(*args, **kwargs)\n",
      "  File \"C:\\Users\\14435\\anaconda3\\envs\\tensorflow\\lib\\site-packages\\IPython\\core\\ultratb.py\", line 281, in _fixed_getinnerframes\n",
      "    records = fix_frame_records_filenames(inspect.getinnerframes(etb, context))\n",
      "  File \"C:\\Users\\14435\\anaconda3\\envs\\tensorflow\\lib\\inspect.py\", line 1502, in getinnerframes\n",
      "    frameinfo = (tb.tb_frame,) + getframeinfo(tb, context)\n",
      "  File \"C:\\Users\\14435\\anaconda3\\envs\\tensorflow\\lib\\inspect.py\", line 1460, in getframeinfo\n",
      "    filename = getsourcefile(frame) or getfile(frame)\n",
      "  File \"C:\\Users\\14435\\anaconda3\\envs\\tensorflow\\lib\\inspect.py\", line 696, in getsourcefile\n",
      "    if getattr(getmodule(object, filename), '__loader__', None) is not None:\n",
      "  File \"C:\\Users\\14435\\anaconda3\\envs\\tensorflow\\lib\\inspect.py\", line 733, in getmodule\n",
      "    if ismodule(module) and hasattr(module, '__file__'):\n",
      "  File \"C:\\Users\\14435\\anaconda3\\envs\\tensorflow\\lib\\site-packages\\tensorflow\\__init__.py\", line 50, in __getattr__\n",
      "    module = self._load()\n",
      "  File \"C:\\Users\\14435\\anaconda3\\envs\\tensorflow\\lib\\site-packages\\tensorflow\\__init__.py\", line 44, in _load\n",
      "    module = _importlib.import_module(self.__name__)\n",
      "  File \"C:\\Users\\14435\\anaconda3\\envs\\tensorflow\\lib\\importlib\\__init__.py\", line 127, in import_module\n",
      "    return _bootstrap._gcd_import(name[level:], package, level)\n",
      "  File \"<frozen importlib._bootstrap>\", line 1006, in _gcd_import\n",
      "  File \"<frozen importlib._bootstrap>\", line 983, in _find_and_load\n",
      "  File \"<frozen importlib._bootstrap>\", line 953, in _find_and_load_unlocked\n",
      "  File \"<frozen importlib._bootstrap>\", line 219, in _call_with_frames_removed\n",
      "  File \"<frozen importlib._bootstrap>\", line 1006, in _gcd_import\n",
      "  File \"<frozen importlib._bootstrap>\", line 983, in _find_and_load\n",
      "  File \"<frozen importlib._bootstrap>\", line 967, in _find_and_load_unlocked\n",
      "  File \"<frozen importlib._bootstrap>\", line 677, in _load_unlocked\n",
      "  File \"<frozen importlib._bootstrap_external>\", line 728, in exec_module\n",
      "  File \"<frozen importlib._bootstrap>\", line 219, in _call_with_frames_removed\n",
      "  File \"C:\\Users\\14435\\anaconda3\\envs\\tensorflow\\lib\\site-packages\\tensorflow_core\\__init__.py\", line 42, in <module>\n",
      "    from . _api.v2 import audio\n",
      "  File \"C:\\Users\\14435\\anaconda3\\envs\\tensorflow\\lib\\site-packages\\tensorflow_core\\_api\\v2\\audio\\__init__.py\", line 10, in <module>\n",
      "    from tensorflow.python.ops.gen_audio_ops import decode_wav\n",
      "  File \"C:\\Users\\14435\\anaconda3\\envs\\tensorflow\\lib\\site-packages\\tensorflow_core\\python\\ops\\gen_audio_ops.py\", line 10, in <module>\n",
      "    from tensorflow.python.eager import context as _context\n",
      "  File \"C:\\Users\\14435\\anaconda3\\envs\\tensorflow\\lib\\site-packages\\tensorflow_core\\python\\eager\\context.py\", line 29, in <module>\n",
      "    from tensorflow.core.protobuf import config_pb2\n",
      "  File \"C:\\Users\\14435\\anaconda3\\envs\\tensorflow\\lib\\site-packages\\tensorflow_core\\core\\protobuf\\config_pb2.py\", line 16, in <module>\n",
      "    from tensorflow.core.framework import cost_graph_pb2 as tensorflow_dot_core_dot_framework_dot_cost__graph__pb2\n",
      "  File \"C:\\Users\\14435\\anaconda3\\envs\\tensorflow\\lib\\site-packages\\tensorflow_core\\core\\framework\\cost_graph_pb2.py\", line 16, in <module>\n",
      "    from tensorflow.core.framework import tensor_shape_pb2 as tensorflow_dot_core_dot_framework_dot_tensor__shape__pb2\n",
      "  File \"C:\\Users\\14435\\anaconda3\\envs\\tensorflow\\lib\\site-packages\\tensorflow_core\\core\\framework\\tensor_shape_pb2.py\", line 42, in <module>\n",
      "    serialized_options=None, file=DESCRIPTOR),\n",
      "  File \"C:\\Users\\14435\\anaconda3\\envs\\tensorflow\\lib\\site-packages\\google\\protobuf\\descriptor.py\", line 561, in __new__\n",
      "    _message.Message._CheckCalledFromGeneratedFile()\n",
      "TypeError: Descriptors cannot not be created directly.\n",
      "If this call came from a _pb2.py file, your generated code is out of date and must be regenerated with protoc >= 3.19.0.\n",
      "If you cannot immediately regenerate your protos, some other possible workarounds are:\n",
      " 1. Downgrade the protobuf package to 3.20.x or lower.\n",
      " 2. Set PROTOCOL_BUFFERS_PYTHON_IMPLEMENTATION=python (but this will use pure-Python parsing and will be much slower).\n",
      "\n",
      "More information: https://developers.google.com/protocol-buffers/docs/news/2022-05-06#python-updates\n",
      "Traceback (most recent call last):\n",
      "  File \"C:\\Users\\14435\\anaconda3\\envs\\tensorflow\\lib\\site-packages\\IPython\\core\\interactiveshell.py\", line 3457, in run_code\n",
      "    exec(code_obj, self.user_global_ns, self.user_ns)\n",
      "  File \"C:\\Users\\14435\\AppData\\Local\\Temp\\ipykernel_382640\\3027163026.py\", line 1, in <module>\n",
      "    from tensorflow.keras import layers, models, utils\n",
      "  File \"C:\\Users\\14435\\anaconda3\\envs\\tensorflow\\lib\\site-packages\\tensorflow\\__init__.py\", line 101, in <module>\n",
      "    from tensorflow_core import *\n",
      "  File \"C:\\Users\\14435\\anaconda3\\envs\\tensorflow\\lib\\site-packages\\tensorflow_core\\__init__.py\", line 40, in <module>\n",
      "    from tensorflow.python.tools import module_util as _module_util\n",
      "  File \"<frozen importlib._bootstrap>\", line 983, in _find_and_load\n",
      "  File \"<frozen importlib._bootstrap>\", line 959, in _find_and_load_unlocked\n",
      "  File \"C:\\Users\\14435\\anaconda3\\envs\\tensorflow\\lib\\site-packages\\tensorflow\\__init__.py\", line 50, in __getattr__\n",
      "    module = self._load()\n",
      "  File \"C:\\Users\\14435\\anaconda3\\envs\\tensorflow\\lib\\site-packages\\tensorflow\\__init__.py\", line 44, in _load\n",
      "    module = _importlib.import_module(self.__name__)\n",
      "  File \"C:\\Users\\14435\\anaconda3\\envs\\tensorflow\\lib\\importlib\\__init__.py\", line 127, in import_module\n",
      "    return _bootstrap._gcd_import(name[level:], package, level)\n",
      "  File \"C:\\Users\\14435\\anaconda3\\envs\\tensorflow\\lib\\site-packages\\tensorflow_core\\python\\__init__.py\", line 64, in <module>\n",
      "    from tensorflow.core.framework.graph_pb2 import *\n",
      "  File \"C:\\Users\\14435\\anaconda3\\envs\\tensorflow\\lib\\site-packages\\tensorflow_core\\core\\framework\\graph_pb2.py\", line 16, in <module>\n",
      "    from tensorflow.core.framework import node_def_pb2 as tensorflow_dot_core_dot_framework_dot_node__def__pb2\n",
      "  File \"C:\\Users\\14435\\anaconda3\\envs\\tensorflow\\lib\\site-packages\\tensorflow_core\\core\\framework\\node_def_pb2.py\", line 16, in <module>\n",
      "    from tensorflow.core.framework import attr_value_pb2 as tensorflow_dot_core_dot_framework_dot_attr__value__pb2\n",
      "  File \"C:\\Users\\14435\\anaconda3\\envs\\tensorflow\\lib\\site-packages\\tensorflow_core\\core\\framework\\attr_value_pb2.py\", line 16, in <module>\n",
      "    from tensorflow.core.framework import tensor_pb2 as tensorflow_dot_core_dot_framework_dot_tensor__pb2\n",
      "  File \"C:\\Users\\14435\\anaconda3\\envs\\tensorflow\\lib\\site-packages\\tensorflow_core\\core\\framework\\tensor_pb2.py\", line 16, in <module>\n",
      "    from tensorflow.core.framework import resource_handle_pb2 as tensorflow_dot_core_dot_framework_dot_resource__handle__pb2\n",
      "  File \"C:\\Users\\14435\\anaconda3\\envs\\tensorflow\\lib\\site-packages\\tensorflow_core\\core\\framework\\resource_handle_pb2.py\", line 16, in <module>\n",
      "    from tensorflow.core.framework import tensor_shape_pb2 as tensorflow_dot_core_dot_framework_dot_tensor__shape__pb2\n",
      "  File \"C:\\Users\\14435\\anaconda3\\envs\\tensorflow\\lib\\site-packages\\tensorflow_core\\core\\framework\\tensor_shape_pb2.py\", line 42, in <module>\n",
      "    serialized_options=None, file=DESCRIPTOR),\n",
      "  File \"C:\\Users\\14435\\anaconda3\\envs\\tensorflow\\lib\\site-packages\\google\\protobuf\\descriptor.py\", line 561, in __new__\n",
      "    _message.Message._CheckCalledFromGeneratedFile()\n",
      "TypeError: Descriptors cannot not be created directly.\n",
      "If this call came from a _pb2.py file, your generated code is out of date and must be regenerated with protoc >= 3.19.0.\n",
      "If you cannot immediately regenerate your protos, some other possible workarounds are:\n",
      " 1. Downgrade the protobuf package to 3.20.x or lower.\n",
      " 2. Set PROTOCOL_BUFFERS_PYTHON_IMPLEMENTATION=python (but this will use pure-Python parsing and will be much slower).\n",
      "\n",
      "More information: https://developers.google.com/protocol-buffers/docs/news/2022-05-06#python-updates\n",
      "\n",
      "During handling of the above exception, another exception occurred:\n",
      "\n",
      "Traceback (most recent call last):\n",
      "  File \"C:\\Users\\14435\\anaconda3\\envs\\tensorflow\\lib\\site-packages\\IPython\\core\\interactiveshell.py\", line 2077, in showtraceback\n",
      "    stb = value._render_traceback_()\n",
      "AttributeError: 'TypeError' object has no attribute '_render_traceback_'\n",
      "\n",
      "During handling of the above exception, another exception occurred:\n",
      "\n",
      "Traceback (most recent call last):\n",
      "  File \"C:\\Users\\14435\\anaconda3\\envs\\tensorflow\\lib\\site-packages\\IPython\\core\\interactiveshell.py\", line 3377, in run_ast_nodes\n",
      "    if (await self.run_code(code, result,  async_=asy)):\n",
      "  File \"C:\\Users\\14435\\anaconda3\\envs\\tensorflow\\lib\\site-packages\\IPython\\core\\interactiveshell.py\", line 3474, in run_code\n",
      "    self.showtraceback(running_compiled_code=True)\n",
      "  File \"C:\\Users\\14435\\anaconda3\\envs\\tensorflow\\lib\\site-packages\\IPython\\core\\interactiveshell.py\", line 2080, in showtraceback\n",
      "    value, tb, tb_offset=tb_offset)\n",
      "  File \"C:\\Users\\14435\\anaconda3\\envs\\tensorflow\\lib\\site-packages\\IPython\\core\\ultratb.py\", line 1368, in structured_traceback\n",
      "    self, etype, value, tb, tb_offset, number_of_lines_of_context)\n",
      "  File \"C:\\Users\\14435\\anaconda3\\envs\\tensorflow\\lib\\site-packages\\IPython\\core\\ultratb.py\", line 1268, in structured_traceback\n",
      "    self, etype, value, tb, tb_offset, number_of_lines_of_context\n",
      "  File \"C:\\Users\\14435\\anaconda3\\envs\\tensorflow\\lib\\site-packages\\IPython\\core\\ultratb.py\", line 1125, in structured_traceback\n",
      "    tb_offset)\n",
      "  File \"C:\\Users\\14435\\anaconda3\\envs\\tensorflow\\lib\\site-packages\\IPython\\core\\ultratb.py\", line 1082, in format_exception_as_a_whole\n",
      "    last_unique, recursion_repeat = find_recursion(orig_etype, evalue, records)\n",
      "  File \"C:\\Users\\14435\\anaconda3\\envs\\tensorflow\\lib\\site-packages\\IPython\\core\\ultratb.py\", line 382, in find_recursion\n",
      "    return len(records), 0\n",
      "TypeError: object of type 'NoneType' has no len()\n",
      "\n",
      "During handling of the above exception, another exception occurred:\n",
      "\n",
      "Traceback (most recent call last):\n",
      "  File \"C:\\Users\\14435\\anaconda3\\envs\\tensorflow\\lib\\site-packages\\IPython\\core\\interactiveshell.py\", line 2077, in showtraceback\n",
      "    stb = value._render_traceback_()\n",
      "AttributeError: 'TypeError' object has no attribute '_render_traceback_'\n",
      "\n",
      "During handling of the above exception, another exception occurred:\n",
      "\n",
      "Traceback (most recent call last):\n",
      "  File \"C:\\Users\\14435\\anaconda3\\envs\\tensorflow\\lib\\site-packages\\IPython\\core\\interactiveshell.py\", line 2960, in _run_cell\n",
      "    return runner(coro)\n",
      "  File \"C:\\Users\\14435\\anaconda3\\envs\\tensorflow\\lib\\site-packages\\IPython\\core\\async_helpers.py\", line 78, in _pseudo_sync_runner\n",
      "    coro.send(None)\n",
      "  File \"C:\\Users\\14435\\anaconda3\\envs\\tensorflow\\lib\\site-packages\\IPython\\core\\interactiveshell.py\", line 3186, in run_cell_async\n",
      "    interactivity=interactivity, compiler=compiler, result=result)\n",
      "  File \"C:\\Users\\14435\\anaconda3\\envs\\tensorflow\\lib\\site-packages\\IPython\\core\\interactiveshell.py\", line 3396, in run_ast_nodes\n",
      "    self.showtraceback()\n",
      "  File \"C:\\Users\\14435\\anaconda3\\envs\\tensorflow\\lib\\site-packages\\IPython\\core\\interactiveshell.py\", line 2080, in showtraceback\n",
      "    value, tb, tb_offset=tb_offset)\n",
      "  File \"C:\\Users\\14435\\anaconda3\\envs\\tensorflow\\lib\\site-packages\\IPython\\core\\ultratb.py\", line 1368, in structured_traceback\n",
      "    self, etype, value, tb, tb_offset, number_of_lines_of_context)\n",
      "  File \"C:\\Users\\14435\\anaconda3\\envs\\tensorflow\\lib\\site-packages\\IPython\\core\\ultratb.py\", line 1268, in structured_traceback\n",
      "    self, etype, value, tb, tb_offset, number_of_lines_of_context\n",
      "  File \"C:\\Users\\14435\\anaconda3\\envs\\tensorflow\\lib\\site-packages\\IPython\\core\\ultratb.py\", line 1143, in structured_traceback\n",
      "    chained_exceptions_tb_offset)\n",
      "  File \"C:\\Users\\14435\\anaconda3\\envs\\tensorflow\\lib\\site-packages\\IPython\\core\\ultratb.py\", line 1082, in format_exception_as_a_whole\n",
      "    last_unique, recursion_repeat = find_recursion(orig_etype, evalue, records)\n",
      "  File \"C:\\Users\\14435\\anaconda3\\envs\\tensorflow\\lib\\site-packages\\IPython\\core\\ultratb.py\", line 382, in find_recursion\n",
      "    return len(records), 0\n",
      "TypeError: object of type 'NoneType' has no len()\n",
      "\n",
      "During handling of the above exception, another exception occurred:\n",
      "\n",
      "Traceback (most recent call last):\n",
      "  File \"C:\\Users\\14435\\anaconda3\\envs\\tensorflow\\lib\\site-packages\\IPython\\core\\interactiveshell.py\", line 2077, in showtraceback\n",
      "    stb = value._render_traceback_()\n",
      "AttributeError: 'TypeError' object has no attribute '_render_traceback_'\n",
      "\n",
      "During handling of the above exception, another exception occurred:\n",
      "\n",
      "Traceback (most recent call last):\n",
      "  File \"C:\\Users\\14435\\anaconda3\\envs\\tensorflow\\lib\\site-packages\\IPython\\core\\ultratb.py\", line 1101, in get_records\n",
      "    return _fixed_getinnerframes(etb, number_of_lines_of_context, tb_offset)\n",
      "  File \"C:\\Users\\14435\\anaconda3\\envs\\tensorflow\\lib\\site-packages\\IPython\\core\\ultratb.py\", line 248, in wrapped\n",
      "    return f(*args, **kwargs)\n",
      "  File \"C:\\Users\\14435\\anaconda3\\envs\\tensorflow\\lib\\site-packages\\IPython\\core\\ultratb.py\", line 281, in _fixed_getinnerframes\n",
      "    records = fix_frame_records_filenames(inspect.getinnerframes(etb, context))\n",
      "  File \"C:\\Users\\14435\\anaconda3\\envs\\tensorflow\\lib\\inspect.py\", line 1502, in getinnerframes\n",
      "    frameinfo = (tb.tb_frame,) + getframeinfo(tb, context)\n",
      "  File \"C:\\Users\\14435\\anaconda3\\envs\\tensorflow\\lib\\inspect.py\", line 1460, in getframeinfo\n",
      "    filename = getsourcefile(frame) or getfile(frame)\n",
      "  File \"C:\\Users\\14435\\anaconda3\\envs\\tensorflow\\lib\\inspect.py\", line 696, in getsourcefile\n",
      "    if getattr(getmodule(object, filename), '__loader__', None) is not None:\n",
      "  File \"C:\\Users\\14435\\anaconda3\\envs\\tensorflow\\lib\\inspect.py\", line 733, in getmodule\n",
      "    if ismodule(module) and hasattr(module, '__file__'):\n",
      "  File \"C:\\Users\\14435\\anaconda3\\envs\\tensorflow\\lib\\site-packages\\tensorflow\\__init__.py\", line 50, in __getattr__\n",
      "    module = self._load()\n",
      "  File \"C:\\Users\\14435\\anaconda3\\envs\\tensorflow\\lib\\site-packages\\tensorflow\\__init__.py\", line 44, in _load\n",
      "    module = _importlib.import_module(self.__name__)\n",
      "  File \"C:\\Users\\14435\\anaconda3\\envs\\tensorflow\\lib\\importlib\\__init__.py\", line 127, in import_module\n",
      "    return _bootstrap._gcd_import(name[level:], package, level)\n",
      "  File \"<frozen importlib._bootstrap>\", line 1006, in _gcd_import\n",
      "  File \"<frozen importlib._bootstrap>\", line 983, in _find_and_load\n",
      "  File \"<frozen importlib._bootstrap>\", line 953, in _find_and_load_unlocked\n",
      "  File \"<frozen importlib._bootstrap>\", line 219, in _call_with_frames_removed\n",
      "  File \"<frozen importlib._bootstrap>\", line 1006, in _gcd_import\n",
      "  File \"<frozen importlib._bootstrap>\", line 983, in _find_and_load\n",
      "  File \"<frozen importlib._bootstrap>\", line 967, in _find_and_load_unlocked\n",
      "  File \"<frozen importlib._bootstrap>\", line 677, in _load_unlocked\n",
      "  File \"<frozen importlib._bootstrap_external>\", line 728, in exec_module\n",
      "  File \"<frozen importlib._bootstrap>\", line 219, in _call_with_frames_removed\n",
      "  File \"C:\\Users\\14435\\anaconda3\\envs\\tensorflow\\lib\\site-packages\\tensorflow_core\\__init__.py\", line 42, in <module>\n",
      "    from . _api.v2 import audio\n",
      "  File \"C:\\Users\\14435\\anaconda3\\envs\\tensorflow\\lib\\site-packages\\tensorflow_core\\_api\\v2\\audio\\__init__.py\", line 10, in <module>\n",
      "    from tensorflow.python.ops.gen_audio_ops import decode_wav\n",
      "  File \"C:\\Users\\14435\\anaconda3\\envs\\tensorflow\\lib\\site-packages\\tensorflow_core\\python\\ops\\gen_audio_ops.py\", line 10, in <module>\n",
      "    from tensorflow.python.eager import context as _context\n",
      "  File \"C:\\Users\\14435\\anaconda3\\envs\\tensorflow\\lib\\site-packages\\tensorflow_core\\python\\eager\\context.py\", line 29, in <module>\n",
      "    from tensorflow.core.protobuf import config_pb2\n",
      "  File \"C:\\Users\\14435\\anaconda3\\envs\\tensorflow\\lib\\site-packages\\tensorflow_core\\core\\protobuf\\config_pb2.py\", line 16, in <module>\n",
      "    from tensorflow.core.framework import cost_graph_pb2 as tensorflow_dot_core_dot_framework_dot_cost__graph__pb2\n",
      "  File \"C:\\Users\\14435\\anaconda3\\envs\\tensorflow\\lib\\site-packages\\tensorflow_core\\core\\framework\\cost_graph_pb2.py\", line 16, in <module>\n",
      "    from tensorflow.core.framework import tensor_shape_pb2 as tensorflow_dot_core_dot_framework_dot_tensor__shape__pb2\n",
      "  File \"C:\\Users\\14435\\anaconda3\\envs\\tensorflow\\lib\\site-packages\\tensorflow_core\\core\\framework\\tensor_shape_pb2.py\", line 42, in <module>\n",
      "    serialized_options=None, file=DESCRIPTOR),\n",
      "  File \"C:\\Users\\14435\\anaconda3\\envs\\tensorflow\\lib\\site-packages\\google\\protobuf\\descriptor.py\", line 561, in __new__\n",
      "    _message.Message._CheckCalledFromGeneratedFile()\n",
      "TypeError: Descriptors cannot not be created directly.\n",
      "If this call came from a _pb2.py file, your generated code is out of date and must be regenerated with protoc >= 3.19.0.\n",
      "If you cannot immediately regenerate your protos, some other possible workarounds are:\n",
      " 1. Downgrade the protobuf package to 3.20.x or lower.\n",
      " 2. Set PROTOCOL_BUFFERS_PYTHON_IMPLEMENTATION=python (but this will use pure-Python parsing and will be much slower).\n",
      "\n",
      "More information: https://developers.google.com/protocol-buffers/docs/news/2022-05-06#python-updates\n"
     ]
    }
   ],
   "source": [
    "from tensorflow.keras import layers, models, utils\n",
    "import tensorflow as tf\n",
    "from tensorflow import keras"
   ]
  },
  {
   "cell_type": "code",
   "execution_count": null,
   "id": "d469b5da",
   "metadata": {},
   "outputs": [],
   "source": []
  }
 ],
 "metadata": {
  "kernelspec": {
   "display_name": "Python 3 (ipykernel)",
   "language": "python",
   "name": "python3"
  },
  "language_info": {
   "codemirror_mode": {
    "name": "ipython",
    "version": 3
   },
   "file_extension": ".py",
   "mimetype": "text/x-python",
   "name": "python",
   "nbconvert_exporter": "python",
   "pygments_lexer": "ipython3",
   "version": "3.7.16"
  }
 },
 "nbformat": 4,
 "nbformat_minor": 5
}
